Workbook

Sheet STREAM WISE
B1: SRI CHAITANYA EDUCATIONAL INSTITUTIONS
B2: STREAM-WISE_DAILY_ATTENDANCE_REPORT | U2: ='Format-Blr'!U2 -> Date:18-04-2026
A3: CITY | B3: NAME OF THE CAMPUS | C3: RESI. /DAY | D3: BOYS /GIRLS / COED | E3: INCOMING SENIORS | Y3: TOT STR | Z3: TOT PRE | AA3: TOT PRE (%) | AB3: OUTGOING SENIORS | AV3: TOT STR | AW3: TOT PRE | AX3: TOT PRE (%) | AY3: LTC-VAIDYAH | BB3: CO-IPL | BJ3: TOT STR | BK3: TOT PRE | BL3: TOT PRE (%) | BN3: GRAND TOTAL
E4: Super60(N) | G4: Super60(S) | I4: Elite(C-120) | K4: S60(Star) | M4: C120(Star) | O4: JEE Apex | Q4: MPL-ELITE | S4: AIIMS S60 | U4: NEET Wisdom | W4: Sr.ELITE & AS60 (Star) | AB4: Super60(N) | AD4: Super60(S) | AF4: Elite(C-120) | AH4: S60(Star) | AJ4: C120(Star) | AL4: JEE Apex (2Hrs) | AN4: MPL-ELITE | AP4: AIIMS S60 | AR4: NEET Wisdom (2Hrs) | AT4: Sr.ELITE & AS60 (Star) | BB4: 7TH CLASS | BD4: 8TH CLASS | BF4: 9TH CLASS | BH4: 10TH CLASS
E5: STR | F5: PRE | G5: STR | H5: PRE | I5: STR | J5: PRE | K5: STR | L5: PRE | M5: STR | N5: PRE | O5: STR | P5: PRE | Q5: STR | R5: PRE | S5: STR | T5: PRE | U5: STR | V5: PRE | W5: STR | X5: PRE | AB5: STR | AC5: PRE | AD5: STR | AE5: PRE | AF5: STR | AG5: PRE | AH5: STR | AI5: PRE | AJ5: STR | AK5: PRE | AL5: STR | AM5: PRE | AN5: STR | AO5: PRE | AP5: STR | AQ5: PRE | AR5: STR | AS5: PRE | AT5: STR | AU5: PRE | AY5: STR | AZ5: PRE | BA5: PRE (%) | BB5: STR | BC5: PRE | BD5: STR | BE5: PRE | BF5: STR | BG5: PRE | BH5: STR | BI5: PRE | BN5: TOT STR | BO5: TOT PRE | BP5: TOT PRE (%)
A6: BANGALORE | B6: BANASWADI | C6: DAY | D6: COED | E6: =_xlfn.XLOOKUP(B6,'Format-Blr'!$B$7:$B$44,'Format-Blr'!I$7:I$44) -> 0 | F6: =_xlfn.XLOOKUP(B6,'Format-Blr'!$B$7:$B$44,'Format-Blr'!J$7:J$44) -> 0 | G6: =_xlfn.XLOOKUP(B6,'Format-Blr'!$B$7:$B$44,'Format-Blr'!P$7:P$44) -> 0 | H6: =_xlfn.XLOOKUP(B6,'Format-Blr'!$B$7:$B$44,'Format-Blr'!Q$7:Q$44) -> 0 | I6: =_xlfn.XLOOKUP(B6,'Format-Blr'!$B$7:$B$44,'Format-Blr'!W$7:W$44) -> 0 | J6: =_xlfn.XLOOKUP(B6,'Format-Blr'!$B$7:$B$44,'Format-Blr'!X$7:X$44) -> 0 | K6: =_xlfn.XLOOKUP(B6,'Format-Blr'!$B$7:$B$44,'Format-Blr'!AD$7:AD$44) -> 0 | L6: =_xlfn.XLOOKUP(B6,'Format-Blr'!$B$7:$B$44,'Format-Blr'!AE$7:AE$44) -> 0 | M6: =_xlfn.XLOOKUP(B6,'Format-Blr'!$B$7:$B$44,'Format-Blr'!AK$7:AK$44) -> 67 | N6: =_xlfn.XLOOKUP(B6,'Format-Blr'!$B$7:$B$44,'Format-Blr'!AL$7:AL$44) -> 60 | O6: =_xlfn.XLOOKUP(B6,'Format-Blr'!$B$7:$B$44,'Format-Blr'!AR$7:AR$44) -> 57 | P6: =_xlfn.XLOOKUP(B6,'Format-Blr'!$B$7:$B$44,'Format-Blr'!AS$7:AS$44) -> 48 | Q6: =_xlfn.XLOOKUP(B6,'Format-Blr'!$B$7:$B$44,'Format-Blr'!AY$7:AY$44) -> 0 | R6: =_xlfn.XLOOKUP(B6,'Format-Blr'!$B$7:$B$44,'Format-Blr'!AZ$7:AZ$44) -> 0 | S6: =_xlfn.XLOOKUP(B6,'Format-Blr'!$B$7:$B$44,'Format-Blr'!BF$7:BF$44) -> 0 | T6: =_xlfn.XLOOKUP(B6,'Format-Blr'!$B$7:$B$44,'Format-Blr'!BG$7:BG$44) -> 0 | U6: =_xlfn.XLOOKUP(B6,'Format-Blr'!$B$7:$B$44,'Format-Blr'!BM$7:BM$44) -> 0 | V6: =_xlfn.XLOOKUP(B6,'Format-Blr'!$B$7:$B$44,'Format-Blr'!BN$7:BN$44) -> 0 | W6: =_xlfn.XLOOKUP(B6,'Format-Blr'!$B$7:$B$44,'Format-Blr'!BT$7:BT$44) -> 48 | X6: =_xlfn.XLOOKUP(B6,'Format-Blr'!$B$7:$B$44,'Format-Blr'!BU$7:BU$44) -> 42 | Y6: =SUM(E6,G6,I6,K6,M6,O6,Q6,S6,U6,W6) -> 172 | Z6: =SUM(F6,H6,J6,L6,N6,P6,R6,T6,V6,X6) -> 150 | AA6: =Z6/Y6*100 -> 87.209302 | AB6: =_xlfn.XLOOKUP(B6,'Format-Blr'!$B$51:$B$88,'Format-Blr'!I$51:I$88) -> 0 | AC6: =_xlfn.XLOOKUP(B6,'Format-Blr'!$B$51:$B$88,'Format-Blr'!J$51:J$88) -> 0 | AD6: =_xlfn.XLOOKUP(B6,'Format-Blr'!$B$51:$B$88,'Format-Blr'!P$51:P$88) -> 0 | AE6: =_xlfn.XLOOKUP(B6,'Format-Blr'!$B$51:$B$88,'Format-Blr'!Q$51:Q$88) -> 0 | AF6: =_xlfn.XLOOKUP(B6,'Format-Blr'!$B$51:$B$88,'Format-Blr'!W$51:W$88) -> 3 | AG6: =_xlfn.XLOOKUP(B6,'Format-Blr'!$B$51:$B$88,'Format-Blr'!X$51:X$88) -> 1 | AH6: =_xlfn.XLOOKUP(B6,'Format-Blr'!$B$51:$B$88,'Format-Blr'!AD$51:AD$88) -> 0 | AI6: =_xlfn.XLOOKUP(B6,'Format-Blr'!$B$51:$B$88,'Format-Blr'!AE$51:AE$88) -> 0 | AJ6: =_xlfn.XLOOKUP(B6,'Format-Blr'!$B$51:$B$88,'Format-Blr'!AK$51:AK$88) -> 39 | AK6: =_xlfn.XLOOKUP(B6,'Format-Blr'!$B$51:$B$88,'Format-Blr'!AL$51:AL$88) -> 11 | AL6: =_xlfn.XLOOKUP(B6,'Format-Blr'!$B$51:$B$88,'Format-Blr'!AR$51:AR$88) -> 28 | AM6: =_xlfn.XLOOKUP(B6,'Format-Blr'!$B$51:$B$88,'Format-Blr'!AS$51:AS$88) -> 10 | AN6: =_xlfn.XLOOKUP(B6,'Format-Blr'!$B$51:$B$88,'Format-Blr'!AY$51:AY$88) -> 0 | AO6: =_xlfn.XLOOKUP(B6,'Format-Blr'!$B$51:$B$88,'Format-Blr'!AZ$51:AZ$88) -> 0 | AP6: =_xlfn.XLOOKUP(B6,'Format-Blr'!$B$51:$B$88,'Format-Blr'!BF$51:BF$88) -> 5 | AQ6: =_xlfn.XLOOKUP(B6,'Format-Blr'!$B$51:$B$88,'Format-Blr'!BG$51:BG$88) -> 1 | AR6: =_xlfn.XLOOKUP(B6,'Format-Blr'!$B$51:$B$88,'Format-Blr'!BM$51:BM$88) -> 0 | AS6: =_xlfn.XLOOKUP(B6,'Format-Blr'!$B$51:$B$88,'Format-Blr'!BN$51:BN$88) -> 0 | AT6: =_xlfn.XLOOKUP(B6,'Format-Blr'!$B$51:$B$88,'Format-Blr'!BT$51:BT$88) -> 40 | AU6: =_xlfn.XLOOKUP(B6,'Format-Blr'!$B$51:$B$88,'Format-Blr'!BU$51:BU$88) -> 6 | AV6: =SUM(AB6,AD6,AF6,AH6,AJ6,AL6,AN6,AP6,AR6,AT6) -> 115 | AW6: =SUM(AC6,AE6,AG6,AI6,AK6,AM6,AO6,AQ6,AS6,AU6) -> 29 | AX6: =AW6/AV6*100 -> 25.217391 | AY6: =_xlfn.XLOOKUP(B6,'Format-Blr'!B$51:B$88,'Format-Blr'!CF$51:CF$88) -> 0 | AZ6: =_xlfn.XLOOKUP(B6,'Format-Blr'!B$51:B$88,'Format-Blr'!CG$51:CG$88) -> 0 | BA6: =AZ6/AY6*100 -> #DIV/0! | BB6: =_xlfn.XLOOKUP(B6,'Format-Blr'!$B$7:$B$44,'Format-Blr'!CF$7:CF$44) -> 0 | BC6: =_xlfn.XLOOKUP(B6,'Format-Blr'!$B$7:$B$44,'Format-Blr'!CG$7:CG$44) -> 0 | BD6: =_xlfn.XLOOKUP(B6,'Format-Blr'!$B$7:$B$44,'Format-Blr'!CI$7:CI$44) -> 0 | BE6: =_xlfn.XLOOKUP(B6,'Format-Blr'!$B$7:$B$44,'Format-Blr'!CJ$7:CJ$44) -> 0 | BF6: =_xlfn.XLOOKUP(B6,'Format-Blr'!$B$7:$B$44,'Format-Blr'!CL$7:CL$44) -> 0 | BG6: =_xlfn.XLOOKUP(B6,'Format-Blr'!$B$7:$B$44,'Format-Blr'!CM$7:CM$44) -> 0 | BH6: =_xlfn.XLOOKUP(B6,'Format-Blr'!$B$7:$B$44,'Format-Blr'!CO$7:CO$44) -> 0 | BI6: =_xlfn.XLOOKUP(B6,'Format-Blr'!$B$7:$B$44,'Format-Blr'!CP$7:CP$44) -> 0 | BJ6: =SUM(BB6,BD6,BF6,BH6) -> 0 | BK6: =SUM(BC6,BE6,BG6,BI6) -> 0 | BL6: =BK6/BJ6*100 -> #DIV/0! | BN6: =SUM(Y6,AV6,AY6,BJ6) -> 287 | BO6: =SUM(Z6,AW6,AZ6,BK6) -> 179 | BP6: =BO6/BN6*100 -> 62.369338
A7: BANGALORE | B7: HORAMAVU | C7: DAY | D7: COED | E7: =_xlfn.XLOOKUP(B7,'Format-Blr'!$B$7:$B$44,'Format-Blr'!I$7:I$44) -> 4 | F7: =_xlfn.XLOOKUP(B7,'Format-Blr'!$B$7:$B$44,'Format-Blr'!J$7:J$44) -> 4 | G7: =_xlfn.XLOOKUP(B7,'Format-Blr'!$B$7:$B$44,'Format-Blr'!P$7:P$44) -> 38 | H7: =_xlfn.XLOOKUP(B7,'Format-Blr'!$B$7:$B$44,'Format-Blr'!Q$7:Q$44) -> 36 | I7: =_xlfn.XLOOKUP(B7,'Format-Blr'!$B$7:$B$44,'Format-Blr'!W$7:W$44) -> 115 | J7: =_xlfn.XLOOKUP(B7,'Format-Blr'!$B$7:$B$44,'Format-Blr'!X$7:X$44) -> 95 | K7: =_xlfn.XLOOKUP(B7,'Format-Blr'!$B$7:$B$44,'Format-Blr'!AD$7:AD$44) -> 0 | L7: =_xlfn.XLOOKUP(B7,'Format-Blr'!$B$7:$B$44,'Format-Blr'!AE$7:AE$44) -> 0 | M7: =_xlfn.XLOOKUP(B7,'Format-Blr'!$B$7:$B$44,'Format-Blr'!AK$7:AK$44) -> 52 | N7: =_xlfn.XLOOKUP(B7,'Format-Blr'!$B$7:$B$44,'Format-Blr'!AL$7:AL$44) -> 45 | O7: =_xlfn.XLOOKUP(B7,'Format-Blr'!$B$7:$B$44,'Format-Blr'!AR$7:AR$44) -> 92 | P7: =_xlfn.XLOOKUP(B7,'Format-Blr'!$B$7:$B$44,'Format-Blr'!AS$7:AS$44) -> 84 | Q7: =_xlfn.XLOOKUP(B7,'Format-Blr'!$B$7:$B$44,'Format-Blr'!AY$7:AY$44) -> 52 | R7: =_xlfn.XLOOKUP(B7,'Format-Blr'!$B$7:$B$44,'Format-Blr'!AZ$7:AZ$44) -> 45 | S7: =_xlfn.XLOOKUP(B7,'Format-Blr'!$B$7:$B$44,'Format-Blr'!BF$7:BF$44) -> 0 | T7: =_xlfn.XLOOKUP(B7,'Format-Blr'!$B$7:$B$44,'Format-Blr'!BG$7:BG$44) -> 0 | U7: =_xlfn.XLOOKUP(B7,'Format-Blr'!$B$7:$B$44,'Format-Blr'!BM$7:BM$44) -> 0 | V7: =_xlfn.XLOOKUP(B7,'Format-Blr'!$B$7:$B$44,'Format-Blr'!BN$7:BN$44) -> 0 | W7: =_xlfn.XLOOKUP(B7,'Format-Blr'!$B$7:$B$44,'Format-Blr'!BT$7:BT$44) -> 48 | X7: =_xlfn.XLOOKUP(B7,'Format-Blr'!$B$7:$B$44,'Format-Blr'!BU$7:BU$44) -> 42 | Y7: =SUM(E7,G7,I7,K7,M7,O7,Q7,S7,U7,W7) -> 401 | Z7: =SUM(F7,H7,J7,L7,N7,P7,R7,T7,V7,X7) -> 351 | AA7: =Z7/Y7*100 -> 87.531172 | AB7: =_xlfn.XLOOKUP(B7,'Format-Blr'!$B$51:$B$88,'Format-Blr'!I$51:I$88) -> 0 | AC7: =_xlfn.XLOOKUP(B7,'Format-Blr'!$B$51:$B$88,'Format-Blr'!J$51:J$88) -> 0 | AD7: =_xlfn.XLOOKUP(B7,'Format-Blr'!$B$51:$B$88,'Format-Blr'!P$51:P$88) -> 36 | AE7: =_xlfn.XLOOKUP(B7,'Format-Blr'!$B$51:$B$88,'Format-Blr'!Q$51:Q$88) -> 4 | AF7: =_xlfn.XLOOKUP(B7,'Format-Blr'!$B$51:$B$88,'Format-Blr'!W$51:W$88) -> 106 | AG7: =_xlfn.XLOOKUP(B7,'Format-Blr'!$B$51:$B$88,'Format-Blr'!X$51:X$88) -> 13 | AH7: =_xlfn.XLOOKUP(B7,'Format-Blr'!$B$51:$B$88,'Format-Blr'!AD$51:AD$88) -> 0 | AI7: =_xlfn.XLOOKUP(B7,'Format-Blr'!$B$51:$B$88,'Format-Blr'!AE$51:AE$88) -> 0 | AJ7: =_xlfn.XLOOKUP(B7,'Format-Blr'!$B$51:$B$88,'Format-Blr'!AK$51:AK$88) -> 56 | AK7: =_xlfn.XLOOKUP(B7,'Format-Blr'!$B$51:$B$88,'Format-Blr'!AL$51:AL$88) -> 10 | AL7: =_xlfn.XLOOKUP(B7,'Format-Blr'!$B$51:$B$88,'Format-Blr'!AR$51:AR$88) -> 99 | AM7: =_xlfn.XLOOKUP(B7,'Format-Blr'!$B$51:$B$88,'Format-Blr'!AS$51:AS$88) -> 4 | AN7: =_xlfn.XLOOKUP(B7,'Format-Blr'!$B$51:$B$88,'Format-Blr'!AY$51:AY$88) -> 51 | AO7: =_xlfn.XLOOKUP(B7,'Format-Blr'!$B$51:$B$88,'Format-Blr'!AZ$51:AZ$88) -> 30 | AP7: =_xlfn.XLOOKUP(B7,'Format-Blr'!$B$51:$B$88,'Format-Blr'!BF$51:BF$88) -> 0 | AQ7: =_xlfn.XLOOKUP(B7,'Format-Blr'!$B$51:$B$88,'Format-Blr'!BG$51:BG$88) -> 0 | AR7: =_xlfn.XLOOKUP(B7,'Format-Blr'!$B$51:$B$88,'Format-Blr'!BM$51:BM$88) -> 0 | AS7: =_xlfn.XLOOKUP(B7,'Format-Blr'!$B$51:$B$88,'Format-Blr'!BN$51:BN$88) -> 0 | AT7: =_xlfn.XLOOKUP(B7,'Format-Blr'!$B$51:$B$88,'Format-Blr'!BT$51:BT$88) -> 37 | AU7: =_xlfn.XLOOKUP(B7,'Format-Blr'!$B$51:$B$88,'Format-Blr'!BU$51:BU$88) -> 0 | AV7: =SUM(AB7,AD7,AF7,AH7,AJ7,AL7,AN7,AP7,AR7,AT7) -> 385 | AW7: =SUM(AC7,AE7,AG7,AI7,AK7,AM7,AO7,AQ7,AS7,AU7) -> 61 | AX7: =AW7/AV7*100 -> 15.844156 | AY7: =_xlfn.XLOOKUP(B7,'Format-Blr'!B$51:B$88,'Format-Blr'!CF$51:CF$88) -> 0 | AZ7: =_xlfn.XLOOKUP(B7,'Format-Blr'!B$51:B$88,'Format-Blr'!CG$51:CG$88) -> 0 | BA7: =AZ7/AY7*100 -> #DIV/0! | BB7: =_xlfn.XLOOKUP(B7,'Format-Blr'!$B$7:$B$44,'Format-Blr'!CF$7:CF$44) -> 26 | BC7: =_xlfn.XLOOKUP(B7,'Format-Blr'!$B$7:$B$44,'Format-Blr'!CG$7:CG$44) -> 0 | BD7: =_xlfn.XLOOKUP(B7,'Format-Blr'!$B$7:$B$44,'Format-Blr'!CI$7:CI$44) -> 48 | BE7: =_xlfn.XLOOKUP(B7,'Format-Blr'!$B$7:$B$44,'Format-Blr'!CJ$7:CJ$44) -> 0 | BF7: =_xlfn.XLOOKUP(B7,'Format-Blr'!$B$7:$B$44,'Format-Blr'!CL$7:CL$44) -> 36 | BG7: =_xlfn.XLOOKUP(B7,'Format-Blr'!$B$7:$B$44,'Format-Blr'!CM$7:CM$44) -> 0 | BH7: =_xlfn.XLOOKUP(B7,'Format-Blr'!$B$7:$B$44,'Format-Blr'!CO$7:CO$44) -> 0 | BI7: =_xlfn.XLOOKUP(B7,'Format-Blr'!$B$7:$B$44,'Format-Blr'!CP$7:CP$44) -> 0 | BJ7: =SUM(BB7,BD7,BF7,BH7) -> 110 | BK7: =SUM(BC7,BE7,BG7,BI7) -> 0 | BL7: =BK7/BJ7*100 -> 0 | BN7: =SUM(Y7,AV7,AY7,BJ7) -> 896 | BO7: =SUM(Z7,AW7,AZ7,BK7) -> 412 | BP7: =BO7/BN7*100 -> 45.982143
A8: BANGALORE | B8: KAGGADASPURA | C8: DAY | D8: COED | E8: =_xlfn.XLOOKUP(B8,'Format-Blr'!$B$7:$B$44,'Format-Blr'!I$7:I$44) -> 0 | F8: =_xlfn.XLOOKUP(B8,'Format-Blr'!$B$7:$B$44,'Format-Blr'!J$7:J$44) -> 0 | G8: =_xlfn.XLOOKUP(B8,'Format-Blr'!$B$7:$B$44,'Format-Blr'!P$7:P$44) -> 0 | H8: =_xlfn.XLOOKUP(B8,'Format-Blr'!$B$7:$B$44,'Format-Blr'!Q$7:Q$44) -> 0 | I8: =_xlfn.XLOOKUP(B8,'Format-Blr'!$B$7:$B$44,'Format-Blr'!W$7:W$44) -> 50 | J8: =_xlfn.XLOOKUP(B8,'Format-Blr'!$B$7:$B$44,'Format-Blr'!X$7:X$44) -> 43 | K8: =_xlfn.XLOOKUP(B8,'Format-Blr'!$B$7:$B$44,'Format-Blr'!AD$7:AD$44) -> 0 | L8: =_xlfn.XLOOKUP(B8,'Format-Blr'!$B$7:$B$44,'Format-Blr'!AE$7:AE$44) -> 0 | M8: =_xlfn.XLOOKUP(B8,'Format-Blr'!$B$7:$B$44,'Format-Blr'!AK$7:AK$44) -> 0 | N8: =_xlfn.XLOOKUP(B8,'Format-Blr'!$B$7:$B$44,'Format-Blr'!AL$7:AL$44) -> 0 | O8: =_xlfn.XLOOKUP(B8,'Format-Blr'!$B$7:$B$44,'Format-Blr'!AR$7:AR$44) -> 51 | P8: =_xlfn.XLOOKUP(B8,'Format-Blr'!$B$7:$B$44,'Format-Blr'!AS$7:AS$44) -> 47 | Q8: =_xlfn.XLOOKUP(B8,'Format-Blr'!$B$7:$B$44,'Format-Blr'!AY$7:AY$44) -> 0 | R8: =_xlfn.XLOOKUP(B8,'Format-Blr'!$B$7:$B$44,'Format-Blr'!AZ$7:AZ$44) -> 0 | S8: =_xlfn.XLOOKUP(B8,'Format-Blr'!$B$7:$B$44,'Format-Blr'!BF$7:BF$44) -> 39 | T8: =_xlfn.XLOOKUP(B8,'Format-Blr'!$B$7:$B$44,'Format-Blr'!BG$7:BG$44) -> 36 | U8: =_xlfn.XLOOKUP(B8,'Format-Blr'!$B$7:$B$44,'Format-Blr'!BM$7:BM$44) -> 0 | V8: =_xlfn.XLOOKUP(B8,'Format-Blr'!$B$7:$B$44,'Format-Blr'!BN$7:BN$44) -> 0 | W8: =_xlfn.XLOOKUP(B8,'Format-Blr'!$B$7:$B$44,'Format-Blr'!BT$7:BT$44) -> 0 | X8: =_xlfn.XLOOKUP(B8,'Format-Blr'!$B$7:$B$44,'Format-Blr'!BU$7:BU$44) -> 0 | Y8: =SUM(E8,G8,I8,K8,M8,O8,Q8,S8,U8,W8) -> 140 | Z8: =SUM(F8,H8,J8,L8,N8,P8,R8,T8,V8,X8) -> 126 | AA8: =Z8/Y8*100 -> 90 | AB8: =_xlfn.XLOOKUP(B8,'Format-Blr'!$B$51:$B$88,'Format-Blr'!I$51:I$88) -> 0 | AC8: =_xlfn.XLOOKUP(B8,'Format-Blr'!$B$51:$B$88,'Format-Blr'!J$51:J$88) -> 0 | AD8: =_xlfn.XLOOKUP(B8,'Format-Blr'!$B$51:$B$88,'Format-Blr'!P$51:P$88) -> 0 | AE8: =_xlfn.XLOOKUP(B8,'Format-Blr'!$B$51:$B$88,'Format-Blr'!Q$51:Q$88) -> 0 | AF8: =_xlfn.XLOOKUP(B8,'Format-Blr'!$B$51:$B$88,'Format-Blr'!W$51:W$88) -> 30 | AG8: =_xlfn.XLOOKUP(B8,'Format-Blr'!$B$51:$B$88,'Format-Blr'!X$51:X$88) -> 0 | AH8: =_xlfn.XLOOKUP(B8,'Format-Blr'!$B$51:$B$88,'Format-Blr'!AD$51:AD$88) -> 0 | AI8: =_xlfn.XLOOKUP(B8,'Format-Blr'!$B$51:$B$88,'Format-Blr'!AE$51:AE$88) -> 0 | AJ8: =_xlfn.XLOOKUP(B8,'Format-Blr'!$B$51:$B$88,'Format-Blr'!AK$51:AK$88) -> 53 | AK8: =_xlfn.XLOOKUP(B8,'Format-Blr'!$B$51:$B$88,'Format-Blr'!AL$51:AL$88) -> 2 | AL8: =_xlfn.XLOOKUP(B8,'Format-Blr'!$B$51:$B$88,'Format-Blr'!AR$51:AR$88) -> 36 | AM8: =_xlfn.XLOOKUP(B8,'Format-Blr'!$B$51:$B$88,'Format-Blr'!AS$51:AS$88) -> 2 | AN8: =_xlfn.XLOOKUP(B8,'Format-Blr'!$B$51:$B$88,'Format-Blr'!AY$51:AY$88) -> 0 | AO8: =_xlfn.XLOOKUP(B8,'Format-Blr'!$B$51:$B$88,'Format-Blr'!AZ$51:AZ$88) -> 0 | AP8: =_xlfn.XLOOKUP(B8,'Format-Blr'!$B$51:$B$88,'Format-Blr'!BF$51:BF$88) -> 48 | AQ8: =_xlfn.XLOOKUP(B8,'Format-Blr'!$B$51:$B$88,'Format-Blr'!BG$51:BG$88) -> 1 | AR8: =_xlfn.XLOOKUP(B8,'Format-Blr'!$B$51:$B$88,'Format-Blr'!BM$51:BM$88) -> 0 | AS8: =_xlfn.XLOOKUP(B8,'Format-Blr'!$B$51:$B$88,'Format-Blr'!BN$51:BN$88) -> 0 | AT8: =_xlfn.XLOOKUP(B8,'Format-Blr'!$B$51:$B$88,'Format-Blr'!BT$51:BT$88) -> 0 | AU8: =_xlfn.XLOOKUP(B8,'Format-Blr'!$B$51:$B$88,'Format-Blr'!BU$51:BU$88) -> 0 | AV8: =SUM(AB8,AD8,AF8,AH8,AJ8,AL8,AN8,AP8,AR8,AT8) -> 167 | AW8: =SUM(AC8,AE8,AG8,AI8,AK8,AM8,AO8,AQ8,AS8,AU8) -> 5 | AX8: =AW8/AV8*100 -> 2.994012 | AY8: =_xlfn.XLOOKUP(B8,'Format-Blr'!B$51:B$88,'Format-Blr'!CF$51:CF$88) -> 0 | AZ8: =_xlfn.XLOOKUP(B8,'Format-Blr'!B$51:B$88,'Format-Blr'!CG$51:CG$88) -> 0 | BA8: =AZ8/AY8*100 -> #DIV/0! | BB8: =_xlfn.XLOOKUP(B8,'Format-Blr'!$B$7:$B$44,'Format-Blr'!CF$7:CF$44) -> 0 | BC8: =_xlfn.XLOOKUP(B8,'Format-Blr'!$B$7:$B$44,'Format-Blr'!CG$7:CG$44) -> 0 | BD8: =_xlfn.XLOOKUP(B8,'Format-Blr'!$B$7:$B$44,'Format-Blr'!CI$7:CI$44) -> 0 | BE8: =_xlfn.XLOOKUP(B8,'Format-Blr'!$B$7:$B$44,'Format-Blr'!CJ$7:CJ$44) -> 0 | BF8: =_xlfn.XLOOKUP(B8,'Format-Blr'!$B$7:$B$44,'Format-Blr'!CL$7:CL$44) -> 0 | BG8: =_xlfn.XLOOKUP(B8,'Format-Blr'!$B$7:$B$44,'Format-Blr'!CM$7:CM$44) -> 0 | BH8: =_xlfn.XLOOKUP(B8,'Format-Blr'!$B$7:$B$44,'Format-Blr'!CO$7:CO$44) -> 0 | BI8: =_xlfn.XLOOKUP(B8,'Format-Blr'!$B$7:$B$44,'Format-Blr'!CP$7:CP$44) -> 0 | BJ8: =SUM(BB8,BD8,BF8,BH8) -> 0 | BK8: =SUM(BC8,BE8,BG8,BI8) -> 0 | BL8: =BK8/BJ8*100 -> #DIV/0! | BN8: =SUM(Y8,AV8,AY8,BJ8) -> 307 | BO8: =SUM(Z8,AW8,AZ8,BK8) -> 131 | BP8: =BO8/BN8*100 -> 42.67101
A9: BANGALORE | B9: KR PURAM | C9: DAY | D9: COED | E9: =_xlfn.XLOOKUP(B9,'Format-Blr'!$B$7:$B$44,'Format-Blr'!I$7:I$44) -> 0 | F9: =_xlfn.XLOOKUP(B9,'Format-Blr'!$B$7:$B$44,'Format-Blr'!J$7:J$44) -> 0 | G9: =_xlfn.XLOOKUP(B9,'Format-Blr'!$B$7:$B$44,'Format-Blr'!P$7:P$44) -> 0 | H9: =_xlfn.XLOOKUP(B9,'Format-Blr'!$B$7:$B$44,'Format-Blr'!Q$7:Q$44) -> 0 | I9: =_xlfn.XLOOKUP(B9,'Format-Blr'!$B$7:$B$44,'Format-Blr'!W$7:W$44) -> 51 | J9: =_xlfn.XLOOKUP(B9,'Format-Blr'!$B$7:$B$44,'Format-Blr'!X$7:X$44) -> 46 | K9: =_xlfn.XLOOKUP(B9,'Format-Blr'!$B$7:$B$44,'Format-Blr'!AD$7:AD$44) -> 0 | L9: =_xlfn.XLOOKUP(B9,'Format-Blr'!$B$7:$B$44,'Format-Blr'!AE$7:AE$44) -> 0 | M9: =_xlfn.XLOOKUP(B9,'Format-Blr'!$B$7:$B$44,'Format-Blr'!AK$7:AK$44) -> 0 | N9: =_xlfn.XLOOKUP(B9,'Format-Blr'!$B$7:$B$44,'Format-Blr'!AL$7:AL$44) -> 0 | O9: =_xlfn.XLOOKUP(B9,'Format-Blr'!$B$7:$B$44,'Format-Blr'!AR$7:AR$44) -> 100 | P9: =_xlfn.XLOOKUP(B9,'Format-Blr'!$B$7:$B$44,'Format-Blr'!AS$7:AS$44) -> 89 | Q9: =_xlfn.XLOOKUP(B9,'Format-Blr'!$B$7:$B$44,'Format-Blr'!AY$7:AY$44) -> 0 | R9: =_xlfn.XLOOKUP(B9,'Format-Blr'!$B$7:$B$44,'Format-Blr'!AZ$7:AZ$44) -> 0 | S9: =_xlfn.XLOOKUP(B9,'Format-Blr'!$B$7:$B$44,'Format-Blr'!BF$7:BF$44) -> 48 | T9: =_xlfn.XLOOKUP(B9,'Format-Blr'!$B$7:$B$44,'Format-Blr'!BG$7:BG$44) -> 41 | U9: =_xlfn.XLOOKUP(B9,'Format-Blr'!$B$7:$B$44,'Format-Blr'!BM$7:BM$44) -> 0 | V9: =_xlfn.XLOOKUP(B9,'Format-Blr'!$B$7:$B$44,'Format-Blr'!BN$7:BN$44) -> 0 | W9: =_xlfn.XLOOKUP(B9,'Format-Blr'!$B$7:$B$44,'Format-Blr'!BT$7:BT$44) -> 0 | X9: =_xlfn.XLOOKUP(B9,'Format-Blr'!$B$7:$B$44,'Format-Blr'!BU$7:BU$44) -> 0 | Y9: =SUM(E9,G9,I9,K9,M9,O9,Q9,S9,U9,W9) -> 199 | Z9: =SUM(F9,H9,J9,L9,N9,P9,R9,T9,V9,X9) -> 176 | AA9: =Z9/Y9*100 -> 88.442211 | AB9: =_xlfn.XLOOKUP(B9,'Format-Blr'!$B$51:$B$88,'Format-Blr'!I$51:I$88) -> 0 | AC9: =_xlfn.XLOOKUP(B9,'Format-Blr'!$B$51:$B$88,'Format-Blr'!J$51:J$88) -> 0 | AD9: =_xlfn.XLOOKUP(B9,'Format-Blr'!$B$51:$B$88,'Format-Blr'!P$51:P$88) -> 0 | AE9: =_xlfn.XLOOKUP(B9,'Format-Blr'!$B$51:$B$88,'Format-Blr'!Q$51:Q$88) -> 0 | AF9: =_xlfn.XLOOKUP(B9,'Format-Blr'!$B$51:$B$88,'Format-Blr'!W$51:W$88) -> 16 | AG9: =_xlfn.XLOOKUP(B9,'Format-Blr'!$B$51:$B$88,'Format-Blr'!X$51:X$88) -> 4 | AH9: =_xlfn.XLOOKUP(B9,'Format-Blr'!$B$51:$B$88,'Format-Blr'!AD$51:AD$88) -> 0 | AI9: =_xlfn.XLOOKUP(B9,'Format-Blr'!$B$51:$B$88,'Format-Blr'!AE$51:AE$88) -> 0 | AJ9: =_xlfn.XLOOKUP(B9,'Format-Blr'!$B$51:$B$88,'Format-Blr'!AK$51:AK$88) -> 49 | AK9: =_xlfn.XLOOKUP(B9,'Format-Blr'!$B$51:$B$88,'Format-Blr'!AL$51:AL$88) -> 6 | AL9: =_xlfn.XLOOKUP(B9,'Format-Blr'!$B$51:$B$88,'Format-Blr'!AR$51:AR$88) -> 36 | AM9: =_xlfn.XLOOKUP(B9,'Format-Blr'!$B$51:$B$88,'Format-Blr'!AS$51:AS$88) -> 7 | AN9: =_xlfn.XLOOKUP(B9,'Format-Blr'!$B$51:$B$88,'Format-Blr'!AY$51:AY$88) -> 22 | AO9: =_xlfn.XLOOKUP(B9,'Format-Blr'!$B$51:$B$88,'Format-Blr'!AZ$51:AZ$88) -> 3 | AP9: =_xlfn.XLOOKUP(B9,'Format-Blr'!$B$51:$B$88,'Format-Blr'!BF$51:BF$88) -> 0 | AQ9: =_xlfn.XLOOKUP(B9,'Format-Blr'!$B$51:$B$88,'Format-Blr'!BG$51:BG$88) -> 0 | AR9: =_xlfn.XLOOKUP(B9,'Format-Blr'!$B$51:$B$88,'Format-Blr'!BM$51:BM$88) -> 42 | AS9: =_xlfn.XLOOKUP(B9,'Format-Blr'!$B$51:$B$88,'Format-Blr'!BN$51:BN$88) -> 8 | AT9: =_xlfn.XLOOKUP(B9,'Format-Blr'!$B$51:$B$88,'Format-Blr'!BT$51:BT$88) -> 0 | AU9: =_xlfn.XLOOKUP(B9,'Format-Blr'!$B$51:$B$88,'Format-Blr'!BU$51:BU$88) -> 0 | AV9: =SUM(AB9,AD9,AF9,AH9,AJ9,AL9,AN9,AP9,AR9,AT9) -> 165 | AW9: =SUM(AC9,AE9,AG9,AI9,AK9,AM9,AO9,AQ9,AS9,AU9) -> 28 | AX9: =AW9/AV9*100 -> 16.969697 | AY9: =_xlfn.XLOOKUP(B9,'Format-Blr'!B$51:B$88,'Format-Blr'!CF$51:CF$88) -> 0 | AZ9: =_xlfn.XLOOKUP(B9,'Format-Blr'!B$51:B$88,'Format-Blr'!CG$51:CG$88) -> 0 | BA9: =AZ9/AY9*100 -> #DIV/0! | BB9: =_xlfn.XLOOKUP(B9,'Format-Blr'!$B$7:$B$44,'Format-Blr'!CF$7:CF$44) -> 0 | BC9: =_xlfn.XLOOKUP(B9,'Format-Blr'!$B$7:$B$44,'Format-Blr'!CG$7:CG$44) -> 0 | BD9: =_xlfn.XLOOKUP(B9,'Format-Blr'!$B$7:$B$44,'Format-Blr'!CI$7:CI$44) -> 0 | BE9: =_xlfn.XLOOKUP(B9,'Format-Blr'!$B$7:$B$44,'Format-Blr'!CJ$7:CJ$44) -> 0 | BF9: =_xlfn.XLOOKUP(B9,'Format-Blr'!$B$7:$B$44,'Format-Blr'!CL$7:CL$44) -> 0 | BG9: =_xlfn.XLOOKUP(B9,'Format-Blr'!$B$7:$B$44,'Format-Blr'!CM$7:CM$44) -> 0 | BH9: =_xlfn.XLOOKUP(B9,'Format-Blr'!$B$7:$B$44,'Format-Blr'!CO$7:CO$44) -> 0 | BI9: =_xlfn.XLOOKUP(B9,'Format-Blr'!$B$7:$B$44,'Format-Blr'!CP$7:CP$44) -> 0 | BJ9: =SUM(BB9,BD9,BF9,BH9) -> 0 | BK9: =SUM(BC9,BE9,BG9,BI9) -> 0 | BL9: =BK9/BJ9*100 -> #DIV/0! | BN9: =SUM(Y9,AV9,AY9,BJ9) -> 364 | BO9: =SUM(Z9,AW9,AZ9,BK9) -> 204 | BP9: =BO9/BN9*100 -> 56.043956
A10: BANGALORE | B10: KUDLU | C10: DAY | D10: COED | E10: =_xlfn.XLOOKUP(B10,'Format-Blr'!$B$7:$B$44,'Format-Blr'!I$7:I$44) -> 0 | F10: =_xlfn.XLOOKUP(B10,'Format-Blr'!$B$7:$B$44,'Format-Blr'!J$7:J$44) -> 0 | G10: =_xlfn.XLOOKUP(B10,'Format-Blr'!$B$7:$B$44,'Format-Blr'!P$7:P$44) -> 44 | H10: =_xlfn.XLOOKUP(B10,'Format-Blr'!$B$7:$B$44,'Format-Blr'!Q$7:Q$44) -> 40 | I10: =_xlfn.XLOOKUP(B10,'Format-Blr'!$B$7:$B$44,'Format-Blr'!W$7:W$44) -> 46 | J10: =_xlfn.XLOOKUP(B10,'Format-Blr'!$B$7:$B$44,'Format-Blr'!X$7:X$44) -> 42 | K10: =_xlfn.XLOOKUP(B10,'Format-Blr'!$B$7:$B$44,'Format-Blr'!AD$7:AD$44) -> 0 | L10: =_xlfn.XLOOKUP(B10,'Format-Blr'!$B$7:$B$44,'Format-Blr'!AE$7:AE$44) -> 0 | M10: =_xlfn.XLOOKUP(B10,'Format-Blr'!$B$7:$B$44,'Format-Blr'!AK$7:AK$44) -> 34 | N10: =_xlfn.XLOOKUP(B10,'Format-Blr'!$B$7:$B$44,'Format-Blr'!AL$7:AL$44) -> 31 | O10: =_xlfn.XLOOKUP(B10,'Format-Blr'!$B$7:$B$44,'Format-Blr'!AR$7:AR$44) -> 41 | P10: =_xlfn.XLOOKUP(B10,'Format-Blr'!$B$7:$B$44,'Format-Blr'!AS$7:AS$44) -> 36 | Q10: =_xlfn.XLOOKUP(B10,'Format-Blr'!$B$7:$B$44,'Format-Blr'!AY$7:AY$44) -> 0 | R10: =_xlfn.XLOOKUP(B10,'Format-Blr'!$B$7:$B$44,'Format-Blr'!AZ$7:AZ$44) -> 0 | S10: =_xlfn.XLOOKUP(B10,'Format-Blr'!$B$7:$B$44,'Format-Blr'!BF$7:BF$44) -> 47 | T10: =_xlfn.XLOOKUP(B10,'Format-Blr'!$B$7:$B$44,'Format-Blr'!BG$7:BG$44) -> 43 | U10: =_xlfn.XLOOKUP(B10,'Format-Blr'!$B$7:$B$44,'Format-Blr'!BM$7:BM$44) -> 0 | V10: =_xlfn.XLOOKUP(B10,'Format-Blr'!$B$7:$B$44,'Format-Blr'!BN$7:BN$44) -> 0 | W10: =_xlfn.XLOOKUP(B10,'Format-Blr'!$B$7:$B$44,'Format-Blr'!BT$7:BT$44) -> 29 | X10: =_xlfn.XLOOKUP(B10,'Format-Blr'!$B$7:$B$44,'Format-Blr'!BU$7:BU$44) -> 27 | Y10: =SUM(E10,G10,I10,K10,M10,O10,Q10,S10,U10,W10) -> 241 | Z10: =SUM(F10,H10,J10,L10,N10,P10,R10,T10,V10,X10) -> 219 | AA10: =Z10/Y10*100 -> 90.871369 | AB10: =_xlfn.XLOOKUP(B10,'Format-Blr'!$B$51:$B$88,'Format-Blr'!I$51:I$88) -> 0 | AC10: =_xlfn.XLOOKUP(B10,'Format-Blr'!$B$51:$B$88,'Format-Blr'!J$51:J$88) -> 0 | AD10: =_xlfn.XLOOKUP(B10,'Format-Blr'!$B$51:$B$88,'Format-Blr'!P$51:P$88) -> 17 | AE10: =_xlfn.XLOOKUP(B10,'Format-Blr'!$B$51:$B$88,'Format-Blr'!Q$51:Q$88) -> 10 | AF10: =_xlfn.XLOOKUP(B10,'Format-Blr'!$B$51:$B$88,'Format-Blr'!W$51:W$88) -> 55 | AG10: =_xlfn.XLOOKUP(B10,'Format-Blr'!$B$51:$B$88,'Format-Blr'!X$51:X$88) -> 4 | AH10: =_xlfn.XLOOKUP(B10,'Format-Blr'!$B$51:$B$88,'Format-Blr'!AD$51:AD$88) -> 0 | AI10: =_xlfn.XLOOKUP(B10,'Format-Blr'!$B$51:$B$88,'Format-Blr'!AE$51:AE$88) -> 0 | AJ10: =_xlfn.XLOOKUP(B10,'Format-Blr'!$B$51:$B$88,'Format-Blr'!AK$51:AK$88) -> 0 | AK10: =_xlfn.XLOOKUP(B10,'Format-Blr'!$B$51:$B$88,'Format-Blr'!AL$51:AL$88) -> 0 | AL10: =_xlfn.XLOOKUP(B10,'Format-Blr'!$B$51:$B$88,'Format-Blr'!AR$51:AR$88) -> 57 | AM10: =_xlfn.XLOOKUP(B10,'Format-Blr'!$B$51:$B$88,'Format-Blr'!AS$51:AS$88) -> 5 | AN10: =_xlfn.XLOOKUP(B10,'Format-Blr'!$B$51:$B$88,'Format-Blr'!AY$51:AY$88) -> 0 | AO10: =_xlfn.XLOOKUP(B10,'Format-Blr'!$B$51:$B$88,'Format-Blr'!AZ$51:AZ$88) -> 0 | AP10: =_xlfn.XLOOKUP(B10,'Format-Blr'!$B$51:$B$88,'Format-Blr'!BF$51:BF$88) -> 48 | AQ10: =_xlfn.XLOOKUP(B10,'Format-Blr'!$B$51:$B$88,'Format-Blr'!BG$51:BG$88) -> 11 | AR10: =_xlfn.XLOOKUP(B10,'Format-Blr'!$B$51:$B$88,'Format-Blr'!BM$51:BM$88) -> 10 | AS10: =_xlfn.XLOOKUP(B10,'Format-Blr'!$B$51:$B$88,'Format-Blr'!BN$51:BN$88) -> 2 | AT10: =_xlfn.XLOOKUP(B10,'Format-Blr'!$B$51:$B$88,'Format-Blr'!BT$51:BT$88) -> 0 | AU10: =_xlfn.XLOOKUP(B10,'Format-Blr'!$B$51:$B$88,'Format-Blr'!BU$51:BU$88) -> 0 | AV10: =SUM(AB10,AD10,AF10,AH10,AJ10,AL10,AN10,AP10,AR10,AT10) -> 187 | AW10: =SUM(AC10,AE10,AG10,AI10,AK10,AM10,AO10,AQ10,AS10,AU10) -> 32 | AX10: =AW10/AV10*100 -> 17.112299 | AY10: =_xlfn.XLOOKUP(B10,'Format-Blr'!B$51:B$88,'Format-Blr'!CF$51:CF$88) -> 0 | AZ10: =_xlfn.XLOOKUP(B10,'Format-Blr'!B$51:B$88,'Format-Blr'!CG$51:CG$88) -> 0 | BA10: =AZ10/AY10*100 -> #DIV/0! | BB10: =_xlfn.XLOOKUP(B10,'Format-Blr'!$B$7:$B$44,'Format-Blr'!CF$7:CF$44) -> 0 | BC10: =_xlfn.XLOOKUP(B10,'Format-Blr'!$B$7:$B$44,'Format-Blr'!CG$7:CG$44) -> 0 | BD10: =_xlfn.XLOOKUP(B10,'Format-Blr'!$B$7:$B$44,'Format-Blr'!CI$7:CI$44) -> 0 | BE10: =_xlfn.XLOOKUP(B10,'Format-Blr'!$B$7:$B$44,'Format-Blr'!CJ$7:CJ$44) -> 0 | BF10: =_xlfn.XLOOKUP(B10,'Format-Blr'!$B$7:$B$44,'Format-Blr'!CL$7:CL$44) -> 0 | BG10: =_xlfn.XLOOKUP(B10,'Format-Blr'!$B$7:$B$44,'Format-Blr'!CM$7:CM$44) -> 0 | BH10: =_xlfn.XLOOKUP(B10,'Format-Blr'!$B$7:$B$44,'Format-Blr'!CO$7:CO$44) -> 0 | BI10: =_xlfn.XLOOKUP(B10,'Format-Blr'!$B$7:$B$44,'Format-Blr'!CP$7:CP$44) -> 0 | BJ10: =SUM(BB10,BD10,BF10,BH10) -> 0 | BK10: =SUM(BC10,BE10,BG10,BI10) -> 0 | BL10: =BK10/BJ10*100 -> #DIV/0! | BN10: =SUM(Y10,AV10,AY10,BJ10) -> 428 | BO10: =SUM(Z10,AW10,AZ10,BK10) -> 251 | BP10: =BO10/BN10*100 -> 58.64486
A11: BANGALORE | B11: MARTHAHALLI | C11: D&R | D11: COED | E11: =_xlfn.XLOOKUP(B11,'Format-Blr'!$B$7:$B$44,'Format-Blr'!I$7:I$44) -> 161 | F11: =_xlfn.XLOOKUP(B11,'Format-Blr'!$B$7:$B$44,'Format-Blr'!J$7:J$44) -> 149 | G11: =_xlfn.XLOOKUP(B11,'Format-Blr'!$B$7:$B$44,'Format-Blr'!P$7:P$44) -> 236 | H11: =_xlfn.XLOOKUP(B11,'Format-Blr'!$B$7:$B$44,'Format-Blr'!Q$7:Q$44) -> 216 | I11: =_xlfn.XLOOKUP(B11,'Format-Blr'!$B$7:$B$44,'Format-Blr'!W$7:W$44) -> 0 | J11: =_xlfn.XLOOKUP(B11,'Format-Blr'!$B$7:$B$44,'Format-Blr'!X$7:X$44) -> 0 | K11: =_xlfn.XLOOKUP(B11,'Format-Blr'!$B$7:$B$44,'Format-Blr'!AD$7:AD$44) -> 0 | L11: =_xlfn.XLOOKUP(B11,'Format-Blr'!$B$7:$B$44,'Format-Blr'!AE$7:AE$44) -> 0 | M11: =_xlfn.XLOOKUP(B11,'Format-Blr'!$B$7:$B$44,'Format-Blr'!AK$7:AK$44) -> 0 | N11: =_xlfn.XLOOKUP(B11,'Format-Blr'!$B$7:$B$44,'Format-Blr'!AL$7:AL$44) -> 0 | O11: =_xlfn.XLOOKUP(B11,'Format-Blr'!$B$7:$B$44,'Format-Blr'!AR$7:AR$44) -> 0 | P11: =_xlfn.XLOOKUP(B11,'Format-Blr'!$B$7:$B$44,'Format-Blr'!AS$7:AS$44) -> 0 | Q11: =_xlfn.XLOOKUP(B11,'Format-Blr'!$B$7:$B$44,'Format-Blr'!AY$7:AY$44) -> 153 | R11: =_xlfn.XLOOKUP(B11,'Format-Blr'!$B$7:$B$44,'Format-Blr'!AZ$7:AZ$44) -> 140 | S11: =_xlfn.XLOOKUP(B11,'Format-Blr'!$B$7:$B$44,'Format-Blr'!BF$7:BF$44) -> 0 | T11: =_xlfn.XLOOKUP(B11,'Format-Blr'!$B$7:$B$44,'Format-Blr'!BG$7:BG$44) -> 0 | U11: =_xlfn.XLOOKUP(B11,'Format-Blr'!$B$7:$B$44,'Format-Blr'!BM$7:BM$44) -> 0 | V11: =_xlfn.XLOOKUP(B11,'Format-Blr'!$B$7:$B$44,'Format-Blr'!BN$7:BN$44) -> 0 | W11: =_xlfn.XLOOKUP(B11,'Format-Blr'!$B$7:$B$44,'Format-Blr'!BT$7:BT$44) -> 0 | X11: =_xlfn.XLOOKUP(B11,'Format-Blr'!$B$7:$B$44,'Format-Blr'!BU$7:BU$44) -> 0 | Y11: =SUM(E11,G11,I11,K11,M11,O11,Q11,S11,U11,W11) -> 550 | Z11: =SUM(F11,H11,J11,L11,N11,P11,R11,T11,V11,X11) -> 505 | AA11: =Z11/Y11*100 -> 91.818182 | AB11: =_xlfn.XLOOKUP(B11,'Format-Blr'!$B$51:$B$88,'Format-Blr'!I$51:I$88) -> 121 | AC11: =_xlfn.XLOOKUP(B11,'Format-Blr'!$B$51:$B$88,'Format-Blr'!J$51:J$88) -> 45 | AD11: =_xlfn.XLOOKUP(B11,'Format-Blr'!$B$51:$B$88,'Format-Blr'!P$51:P$88) -> 180 | AE11: =_xlfn.XLOOKUP(B11,'Format-Blr'!$B$51:$B$88,'Format-Blr'!Q$51:Q$88) -> 43 | AF11: =_xlfn.XLOOKUP(B11,'Format-Blr'!$B$51:$B$88,'Format-Blr'!W$51:W$88) -> 0 | AG11: =_xlfn.XLOOKUP(B11,'Format-Blr'!$B$51:$B$88,'Format-Blr'!X$51:X$88) -> 0 | AH11: =_xlfn.XLOOKUP(B11,'Format-Blr'!$B$51:$B$88,'Format-Blr'!AD$51:AD$88) -> 54 | AI11: =_xlfn.XLOOKUP(B11,'Format-Blr'!$B$51:$B$88,'Format-Blr'!AE$51:AE$88) -> 19 | AJ11: =_xlfn.XLOOKUP(B11,'Format-Blr'!$B$51:$B$88,'Format-Blr'!AK$51:AK$88) -> 0 | AK11: =_xlfn.XLOOKUP(B11,'Format-Blr'!$B$51:$B$88,'Format-Blr'!AL$51:AL$88) -> 0 | AL11: =_xlfn.XLOOKUP(B11,'Format-Blr'!$B$51:$B$88,'Format-Blr'!AR$51:AR$88) -> 0 | AM11: =_xlfn.XLOOKUP(B11,'Format-Blr'!$B$51:$B$88,'Format-Blr'!AS$51:AS$88) -> 0 | AN11: =_xlfn.XLOOKUP(B11,'Format-Blr'!$B$51:$B$88,'Format-Blr'!AY$51:AY$88) -> 0 | AO11: =_xlfn.XLOOKUP(B11,'Format-Blr'!$B$51:$B$88,'Format-Blr'!AZ$51:AZ$88) -> 0 | AP11: =_xlfn.XLOOKUP(B11,'Format-Blr'!$B$51:$B$88,'Format-Blr'!BF$51:BF$88) -> 0 | AQ11: =_xlfn.XLOOKUP(B11,'Format-Blr'!$B$51:$B$88,'Format-Blr'!BG$51:BG$88) -> 0 | AR11: =_xlfn.XLOOKUP(B11,'Format-Blr'!$B$51:$B$88,'Format-Blr'!BM$51:BM$88) -> 0 | AS11: =_xlfn.XLOOKUP(B11,'Format-Blr'!$B$51:$B$88,'Format-Blr'!BN$51:BN$88) -> 0 | AT11: =_xlfn.XLOOKUP(B11,'Format-Blr'!$B$51:$B$88,'Format-Blr'!BT$51:BT$88) -> 0 | AU11: =_xlfn.XLOOKUP(B11,'Format-Blr'!$B$51:$B$88,'Format-Blr'!BU$51:BU$88) -> 0 | AV11: =SUM(AB11,AD11,AF11,AH11,AJ11,AL11,AN11,AP11,AR11,AT11) -> 355 | AW11: =SUM(AC11,AE11,AG11,AI11,AK11,AM11,AO11,AQ11,AS11,AU11) -> 107 | AX11: =AW11/AV11*100 -> 30.140845 | AY11: =_xlfn.XLOOKUP(B11,'Format-Blr'!B$51:B$88,'Format-Blr'!CF$51:CF$88) -> 0 | AZ11: =_xlfn.XLOOKUP(B11,'Format-Blr'!B$51:B$88,'Format-Blr'!CG$51:CG$88) -> 0 | BA11: =AZ11/AY11*100 -> #DIV/0! | BB11: =_xlfn.XLOOKUP(B11,'Format-Blr'!$B$7:$B$44,'Format-Blr'!CF$7:CF$44) -> 45 | BC11: =_xlfn.XLOOKUP(B11,'Format-Blr'!$B$7:$B$44,'Format-Blr'!CG$7:CG$44) -> 45 | BD11: =_xlfn.XLOOKUP(B11,'Format-Blr'!$B$7:$B$44,'Format-Blr'!CI$7:CI$44) -> 53 | BE11: =_xlfn.XLOOKUP(B11,'Format-Blr'!$B$7:$B$44,'Format-Blr'!CJ$7:CJ$44) -> 53 | BF11: =_xlfn.XLOOKUP(B11,'Format-Blr'!$B$7:$B$44,'Format-Blr'!CL$7:CL$44) -> 91 | BG11: =_xlfn.XLOOKUP(B11,'Format-Blr'!$B$7:$B$44,'Format-Blr'!CM$7:CM$44) -> 91 | BH11: =_xlfn.XLOOKUP(B11,'Format-Blr'!$B$7:$B$44,'Format-Blr'!CO$7:CO$44) -> 107 | BI11: =_xlfn.XLOOKUP(B11,'Format-Blr'!$B$7:$B$44,'Format-Blr'!CP$7:CP$44) -> 107 | BJ11: =SUM(BB11,BD11,BF11,BH11) -> 296 | BK11: =SUM(BC11,BE11,BG11,BI11) -> 296 | BL11: =BK11/BJ11*100 -> 100 | BN11: =SUM(Y11,AV11,AY11,BJ11) -> 1201 | BO11: =SUM(Z11,AW11,AZ11,BK11) -> 908 | BP11: =BO11/BN11*100 -> 75.603664
A12: BANGALORE | B12: MARTHAHALLI C-120 | C12: DAY | D12: COED | E12: =_xlfn.XLOOKUP(B12,'Format-Blr'!$B$7:$B$44,'Format-Blr'!I$7:I$44) -> 0 | F12: =_xlfn.XLOOKUP(B12,'Format-Blr'!$B$7:$B$44,'Format-Blr'!J$7:J$44) -> 0 | G12: =_xlfn.XLOOKUP(B12,'Format-Blr'!$B$7:$B$44,'Format-Blr'!P$7:P$44) -> 0 | H12: =_xlfn.XLOOKUP(B12,'Format-Blr'!$B$7:$B$44,'Format-Blr'!Q$7:Q$44) -> 0 | I12: =_xlfn.XLOOKUP(B12,'Format-Blr'!$B$7:$B$44,'Format-Blr'!W$7:W$44) -> 154 | J12: =_xlfn.XLOOKUP(B12,'Format-Blr'!$B$7:$B$44,'Format-Blr'!X$7:X$44) -> 134 | K12: =_xlfn.XLOOKUP(B12,'Format-Blr'!$B$7:$B$44,'Format-Blr'!AD$7:AD$44) -> 0 | L12: =_xlfn.XLOOKUP(B12,'Format-Blr'!$B$7:$B$44,'Format-Blr'!AE$7:AE$44) -> 0 | M12: =_xlfn.XLOOKUP(B12,'Format-Blr'!$B$7:$B$44,'Format-Blr'!AK$7:AK$44) -> 55 | N12: =_xlfn.XLOOKUP(B12,'Format-Blr'!$B$7:$B$44,'Format-Blr'!AL$7:AL$44) -> 54 | O12: =_xlfn.XLOOKUP(B12,'Format-Blr'!$B$7:$B$44,'Format-Blr'!AR$7:AR$44) -> 112 | P12: =_xlfn.XLOOKUP(B12,'Format-Blr'!$B$7:$B$44,'Format-Blr'!AS$7:AS$44) -> 98 | Q12: =_xlfn.XLOOKUP(B12,'Format-Blr'!$B$7:$B$44,'Format-Blr'!AY$7:AY$44) -> 0 | R12: =_xlfn.XLOOKUP(B12,'Format-Blr'!$B$7:$B$44,'Format-Blr'!AZ$7:AZ$44) -> 0 | S12: =_xlfn.XLOOKUP(B12,'Format-Blr'!$B$7:$B$44,'Format-Blr'!BF$7:BF$44) -> 65 | T12: =_xlfn.XLOOKUP(B12,'Format-Blr'!$B$7:$B$44,'Format-Blr'!BG$7:BG$44) -> 63 | U12: =_xlfn.XLOOKUP(B12,'Format-Blr'!$B$7:$B$44,'Format-Blr'!BM$7:BM$44) -> 0 | V12: =_xlfn.XLOOKUP(B12,'Format-Blr'!$B$7:$B$44,'Format-Blr'!BN$7:BN$44) -> 0 | W12: =_xlfn.XLOOKUP(B12,'Format-Blr'!$B$7:$B$44,'Format-Blr'!BT$7:BT$44) -> 0 | X12: =_xlfn.XLOOKUP(B12,'Format-Blr'!$B$7:$B$44,'Format-Blr'!BU$7:BU$44) -> 0 | Y12: =SUM(E12,G12,I12,K12,M12,O12,Q12,S12,U12,W12) -> 386 | Z12: =SUM(F12,H12,J12,L12,N12,P12,R12,T12,V12,X12) -> 349 | AA12: =Z12/Y12*100 -> 90.414508 | AB12: =_xlfn.XLOOKUP(B12,'Format-Blr'!$B$51:$B$88,'Format-Blr'!I$51:I$88) -> 0 | AC12: =_xlfn.XLOOKUP(B12,'Format-Blr'!$B$51:$B$88,'Format-Blr'!J$51:J$88) -> 0 | AD12: =_xlfn.XLOOKUP(B12,'Format-Blr'!$B$51:$B$88,'Format-Blr'!P$51:P$88) -> 33 | AE12: =_xlfn.XLOOKUP(B12,'Format-Blr'!$B$51:$B$88,'Format-Blr'!Q$51:Q$88) -> 13 | AF12: =_xlfn.XLOOKUP(B12,'Format-Blr'!$B$51:$B$88,'Format-Blr'!W$51:W$88) -> 126 | AG12: =_xlfn.XLOOKUP(B12,'Format-Blr'!$B$51:$B$88,'Format-Blr'!X$51:X$88) -> 28 | AH12: =_xlfn.XLOOKUP(B12,'Format-Blr'!$B$51:$B$88,'Format-Blr'!AD$51:AD$88) -> 0 | AI12: =_xlfn.XLOOKUP(B12,'Format-Blr'!$B$51:$B$88,'Format-Blr'!AE$51:AE$88) -> 0 | AJ12: =_xlfn.XLOOKUP(B12,'Format-Blr'!$B$51:$B$88,'Format-Blr'!AK$51:AK$88) -> 60 | AK12: =_xlfn.XLOOKUP(B12,'Format-Blr'!$B$51:$B$88,'Format-Blr'!AL$51:AL$88) -> 21 | AL12: =_xlfn.XLOOKUP(B12,'Format-Blr'!$B$51:$B$88,'Format-Blr'!AR$51:AR$88) -> 99 | AM12: =_xlfn.XLOOKUP(B12,'Format-Blr'!$B$51:$B$88,'Format-Blr'!AS$51:AS$88) -> 38 | AN12: =_xlfn.XLOOKUP(B12,'Format-Blr'!$B$51:$B$88,'Format-Blr'!AY$51:AY$88) -> 0 | AO12: =_xlfn.XLOOKUP(B12,'Format-Blr'!$B$51:$B$88,'Format-Blr'!AZ$51:AZ$88) -> 0 | AP12: =_xlfn.XLOOKUP(B12,'Format-Blr'!$B$51:$B$88,'Format-Blr'!BF$51:BF$88) -> 30 | AQ12: =_xlfn.XLOOKUP(B12,'Format-Blr'!$B$51:$B$88,'Format-Blr'!BG$51:BG$88) -> 8 | AR12: =_xlfn.XLOOKUP(B12,'Format-Blr'!$B$51:$B$88,'Format-Blr'!BM$51:BM$88) -> 0 | AS12: =_xlfn.XLOOKUP(B12,'Format-Blr'!$B$51:$B$88,'Format-Blr'!BN$51:BN$88) -> 0 | AT12: =_xlfn.XLOOKUP(B12,'Format-Blr'!$B$51:$B$88,'Format-Blr'!BT$51:BT$88) -> 32 | AU12: =_xlfn.XLOOKUP(B12,'Format-Blr'!$B$51:$B$88,'Format-Blr'!BU$51:BU$88) -> 10 | AV12: =SUM(AB12,AD12,AF12,AH12,AJ12,AL12,AN12,AP12,AR12,AT12) -> 380 | AW12: =SUM(AC12,AE12,AG12,AI12,AK12,AM12,AO12,AQ12,AS12,AU12) -> 118 | AX12: =AW12/AV12*100 -> 31.052632 | AY12: =_xlfn.XLOOKUP(B12,'Format-Blr'!B$51:B$88,'Format-Blr'!CF$51:CF$88) -> 0 | AZ12: =_xlfn.XLOOKUP(B12,'Format-Blr'!B$51:B$88,'Format-Blr'!CG$51:CG$88) -> 0 | BA12: =AZ12/AY12*100 -> #DIV/0! | BB12: =_xlfn.XLOOKUP(B12,'Format-Blr'!$B$7:$B$44,'Format-Blr'!CF$7:CF$44) -> 0 | BC12: =_xlfn.XLOOKUP(B12,'Format-Blr'!$B$7:$B$44,'Format-Blr'!CG$7:CG$44) -> 0 | BD12: =_xlfn.XLOOKUP(B12,'Format-Blr'!$B$7:$B$44,'Format-Blr'!CI$7:CI$44) -> 0 | BE12: =_xlfn.XLOOKUP(B12,'Format-Blr'!$B$7:$B$44,'Format-Blr'!CJ$7:CJ$44) -> 0 | BF12: =_xlfn.XLOOKUP(B12,'Format-Blr'!$B$7:$B$44,'Format-Blr'!CL$7:CL$44) -> 0 | BG12: =_xlfn.XLOOKUP(B12,'Format-Blr'!$B$7:$B$44,'Format-Blr'!CM$7:CM$44) -> 0 | BH12: =_xlfn.XLOOKUP(B12,'Format-Blr'!$B$7:$B$44,'Format-Blr'!CO$7:CO$44) -> 0 | BI12: =_xlfn.XLOOKUP(B12,'Format-Blr'!$B$7:$B$44,'Format-Blr'!CP$7:CP$44) -> 0 | BJ12: =SUM(BB12,BD12,BF12,BH12) -> 0 | BK12: =SUM(BC12,BE12,BG12,BI12) -> 0 | BL12: =BK12/BJ12*100 -> #DIV/0! | BN12: =SUM(Y12,AV12,AY12,BJ12) -> 766 | BO12: =SUM(Z12,AW12,AZ12,BK12) -> 467 | BP12: =BO12/BN12*100 -> 60.966057
A13: BANGALORE | B13: BELLANDUR | C13: D&R | D13: COED | E13: =_xlfn.XLOOKUP(B13,'Format-Blr'!$B$7:$B$44,'Format-Blr'!I$7:I$44) -> 0 | F13: =_xlfn.XLOOKUP(B13,'Format-Blr'!$B$7:$B$44,'Format-Blr'!J$7:J$44) -> 0 | G13: =_xlfn.XLOOKUP(B13,'Format-Blr'!$B$7:$B$44,'Format-Blr'!P$7:P$44) -> 0 | H13: =_xlfn.XLOOKUP(B13,'Format-Blr'!$B$7:$B$44,'Format-Blr'!Q$7:Q$44) -> 0 | I13: =_xlfn.XLOOKUP(B13,'Format-Blr'!$B$7:$B$44,'Format-Blr'!W$7:W$44) -> 0 | J13: =_xlfn.XLOOKUP(B13,'Format-Blr'!$B$7:$B$44,'Format-Blr'!X$7:X$44) -> 0 | K13: =_xlfn.XLOOKUP(B13,'Format-Blr'!$B$7:$B$44,'Format-Blr'!AD$7:AD$44) -> 0 | L13: =_xlfn.XLOOKUP(B13,'Format-Blr'!$B$7:$B$44,'Format-Blr'!AE$7:AE$44) -> 0 | M13: =_xlfn.XLOOKUP(B13,'Format-Blr'!$B$7:$B$44,'Format-Blr'!AK$7:AK$44) -> 0 | N13: =_xlfn.XLOOKUP(B13,'Format-Blr'!$B$7:$B$44,'Format-Blr'!AL$7:AL$44) -> 0 | O13: =_xlfn.XLOOKUP(B13,'Format-Blr'!$B$7:$B$44,'Format-Blr'!AR$7:AR$44) -> 0 | P13: =_xlfn.XLOOKUP(B13,'Format-Blr'!$B$7:$B$44,'Format-Blr'!AS$7:AS$44) -> 0 | Q13: =_xlfn.XLOOKUP(B13,'Format-Blr'!$B$7:$B$44,'Format-Blr'!AY$7:AY$44) -> 71 | R13: =_xlfn.XLOOKUP(B13,'Format-Blr'!$B$7:$B$44,'Format-Blr'!AZ$7:AZ$44) -> 69 | S13: =_xlfn.XLOOKUP(B13,'Format-Blr'!$B$7:$B$44,'Format-Blr'!BF$7:BF$44) -> 0 | T13: =_xlfn.XLOOKUP(B13,'Format-Blr'!$B$7:$B$44,'Format-Blr'!BG$7:BG$44) -> 0 | U13: =_xlfn.XLOOKUP(B13,'Format-Blr'!$B$7:$B$44,'Format-Blr'!BM$7:BM$44) -> 0 | V13: =_xlfn.XLOOKUP(B13,'Format-Blr'!$B$7:$B$44,'Format-Blr'!BN$7:BN$44) -> 0 | W13: =_xlfn.XLOOKUP(B13,'Format-Blr'!$B$7:$B$44,'Format-Blr'!BT$7:BT$44) -> 0 | X13: =_xlfn.XLOOKUP(B13,'Format-Blr'!$B$7:$B$44,'Format-Blr'!BU$7:BU$44) -> 0 | Y13: =SUM(E13,G13,I13,K13,M13,O13,Q13,S13,U13,W13) -> 71 | Z13: =SUM(F13,H13,J13,L13,N13,P13,R13,T13,V13,X13) -> 69 | AA13: =Z13/Y13*100 -> 97.183099 | AB13: =_xlfn.XLOOKUP(B13,'Format-Blr'!$B$51:$B$88,'Format-Blr'!I$51:I$88) -> 0 | AC13: =_xlfn.XLOOKUP(B13,'Format-Blr'!$B$51:$B$88,'Format-Blr'!J$51:J$88) -> 0 | AD13: =_xlfn.XLOOKUP(B13,'Format-Blr'!$B$51:$B$88,'Format-Blr'!P$51:P$88) -> 0 | AE13: =_xlfn.XLOOKUP(B13,'Format-Blr'!$B$51:$B$88,'Format-Blr'!Q$51:Q$88) -> 0 | AF13: =_xlfn.XLOOKUP(B13,'Format-Blr'!$B$51:$B$88,'Format-Blr'!W$51:W$88) -> 0 | AG13: =_xlfn.XLOOKUP(B13,'Format-Blr'!$B$51:$B$88,'Format-Blr'!X$51:X$88) -> 0 | AH13: =_xlfn.XLOOKUP(B13,'Format-Blr'!$B$51:$B$88,'Format-Blr'!AD$51:AD$88) -> 0 | AI13: =_xlfn.XLOOKUP(B13,'Format-Blr'!$B$51:$B$88,'Format-Blr'!AE$51:AE$88) -> 0 | AJ13: =_xlfn.XLOOKUP(B13,'Format-Blr'!$B$51:$B$88,'Format-Blr'!AK$51:AK$88) -> 0 | AK13: =_xlfn.XLOOKUP(B13,'Format-Blr'!$B$51:$B$88,'Format-Blr'!AL$51:AL$88) -> 0 | AL13: =_xlfn.XLOOKUP(B13,'Format-Blr'!$B$51:$B$88,'Format-Blr'!AR$51:AR$88) -> 0 | AM13: =_xlfn.XLOOKUP(B13,'Format-Blr'!$B$51:$B$88,'Format-Blr'!AS$51:AS$88) -> 0 | AN13: =_xlfn.XLOOKUP(B13,'Format-Blr'!$B$51:$B$88,'Format-Blr'!AY$51:AY$88) -> 231 | AO13: =_xlfn.XLOOKUP(B13,'Format-Blr'!$B$51:$B$88,'Format-Blr'!AZ$51:AZ$88) -> 137 | AP13: =_xlfn.XLOOKUP(B13,'Format-Blr'!$B$51:$B$88,'Format-Blr'!BF$51:BF$88) -> 0 | AQ13: =_xlfn.XLOOKUP(B13,'Format-Blr'!$B$51:$B$88,'Format-Blr'!BG$51:BG$88) -> 0 | AR13: =_xlfn.XLOOKUP(B13,'Format-Blr'!$B$51:$B$88,'Format-Blr'!BM$51:BM$88) -> 0 | AS13: =_xlfn.XLOOKUP(B13,'Format-Blr'!$B$51:$B$88,'Format-Blr'!BN$51:BN$88) -> 0 | AT13: =_xlfn.XLOOKUP(B13,'Format-Blr'!$B$51:$B$88,'Format-Blr'!BT$51:BT$88) -> 0 | AU13: =_xlfn.XLOOKUP(B13,'Format-Blr'!$B$51:$B$88,'Format-Blr'!BU$51:BU$88) -> 0 | AV13: =SUM(AB13,AD13,AF13,AH13,AJ13,AL13,AN13,AP13,AR13,AT13) -> 231 | AW13: =SUM(AC13,AE13,AG13,AI13,AK13,AM13,AO13,AQ13,AS13,AU13) -> 137 | AX13: =AW13/AV13*100 -> 59.307359 | AY13: =_xlfn.XLOOKUP(B13,'Format-Blr'!B$51:B$88,'Format-Blr'!CF$51:CF$88) -> 0 | AZ13: =_xlfn.XLOOKUP(B13,'Format-Blr'!B$51:B$88,'Format-Blr'!CG$51:CG$88) -> 0 | BA13: =AZ13/AY13*100 -> #DIV/0! | BB13: =_xlfn.XLOOKUP(B13,'Format-Blr'!$B$7:$B$44,'Format-Blr'!CF$7:CF$44) -> 0 | BC13: =_xlfn.XLOOKUP(B13,'Format-Blr'!$B$7:$B$44,'Format-Blr'!CG$7:CG$44) -> 0 | BD13: =_xlfn.XLOOKUP(B13,'Format-Blr'!$B$7:$B$44,'Format-Blr'!CI$7:CI$44) -> 0 | BE13: =_xlfn.XLOOKUP(B13,'Format-Blr'!$B$7:$B$44,'Format-Blr'!CJ$7:CJ$44) -> 0 | BF13: =_xlfn.XLOOKUP(B13,'Format-Blr'!$B$7:$B$44,'Format-Blr'!CL$7:CL$44) -> 0 | BG13: =_xlfn.XLOOKUP(B13,'Format-Blr'!$B$7:$B$44,'Format-Blr'!CM$7:CM$44) -> 0 | BH13: =_xlfn.XLOOKUP(B13,'Format-Blr'!$B$7:$B$44,'Format-Blr'!CO$7:CO$44) -> 0 | BI13: =_xlfn.XLOOKUP(B13,'Format-Blr'!$B$7:$B$44,'Format-Blr'!CP$7:CP$44) -> 0 | BJ13: =SUM(BB13,BD13,BF13,BH13) -> 0 | BK13: =SUM(BC13,BE13,BG13,BI13) -> 0 | BL13: =BK13/BJ13*100 -> #DIV/0! | BN13: =SUM(Y13,AV13,AY13,BJ13) -> 302 | BO13: =SUM(Z13,AW13,AZ13,BK13) -> 206 | BP13: =BO13/BN13*100 -> 68.211921
A14: BANGALORE | B14: HEGDENAGAR | C14: DAY | D14: COED | E14: =_xlfn.XLOOKUP(B14,'Format-Blr'!$B$7:$B$44,'Format-Blr'!I$7:I$44) -> 0 | F14: =_xlfn.XLOOKUP(B14,'Format-Blr'!$B$7:$B$44,'Format-Blr'!J$7:J$44) -> 0 | G14: =_xlfn.XLOOKUP(B14,'Format-Blr'!$B$7:$B$44,'Format-Blr'!P$7:P$44) -> 0 | H14: =_xlfn.XLOOKUP(B14,'Format-Blr'!$B$7:$B$44,'Format-Blr'!Q$7:Q$44) -> 0 | I14: =_xlfn.XLOOKUP(B14,'Format-Blr'!$B$7:$B$44,'Format-Blr'!W$7:W$44) -> 0 | J14: =_xlfn.XLOOKUP(B14,'Format-Blr'!$B$7:$B$44,'Format-Blr'!X$7:X$44) -> 0 | K14: =_xlfn.XLOOKUP(B14,'Format-Blr'!$B$7:$B$44,'Format-Blr'!AD$7:AD$44) -> 0 | L14: =_xlfn.XLOOKUP(B14,'Format-Blr'!$B$7:$B$44,'Format-Blr'!AE$7:AE$44) -> 0 | M14: =_xlfn.XLOOKUP(B14,'Format-Blr'!$B$7:$B$44,'Format-Blr'!AK$7:AK$44) -> 82 | N14: =_xlfn.XLOOKUP(B14,'Format-Blr'!$B$7:$B$44,'Format-Blr'!AL$7:AL$44) -> 71 | O14: =_xlfn.XLOOKUP(B14,'Format-Blr'!$B$7:$B$44,'Format-Blr'!AR$7:AR$44) -> 0 | P14: =_xlfn.XLOOKUP(B14,'Format-Blr'!$B$7:$B$44,'Format-Blr'!AS$7:AS$44) -> 0 | Q14: =_xlfn.XLOOKUP(B14,'Format-Blr'!$B$7:$B$44,'Format-Blr'!AY$7:AY$44) -> 0 | R14: =_xlfn.XLOOKUP(B14,'Format-Blr'!$B$7:$B$44,'Format-Blr'!AZ$7:AZ$44) -> 0 | S14: =_xlfn.XLOOKUP(B14,'Format-Blr'!$B$7:$B$44,'Format-Blr'!BF$7:BF$44) -> 39 | T14: =_xlfn.XLOOKUP(B14,'Format-Blr'!$B$7:$B$44,'Format-Blr'!BG$7:BG$44) -> 26 | U14: =_xlfn.XLOOKUP(B14,'Format-Blr'!$B$7:$B$44,'Format-Blr'!BM$7:BM$44) -> 0 | V14: =_xlfn.XLOOKUP(B14,'Format-Blr'!$B$7:$B$44,'Format-Blr'!BN$7:BN$44) -> 0 | W14: =_xlfn.XLOOKUP(B14,'Format-Blr'!$B$7:$B$44,'Format-Blr'!BT$7:BT$44) -> 0 | X14: =_xlfn.XLOOKUP(B14,'Format-Blr'!$B$7:$B$44,'Format-Blr'!BU$7:BU$44) -> 0 | Y14: =SUM(E14,G14,I14,K14,M14,O14,Q14,S14,U14,W14) -> 121 | Z14: =SUM(F14,H14,J14,L14,N14,P14,R14,T14,V14,X14) -> 97 | AA14: =Z14/Y14*100 -> 80.165289 | AB14: =_xlfn.XLOOKUP(B14,'Format-Blr'!$B$51:$B$88,'Format-Blr'!I$51:I$88) -> 0 | AC14: =_xlfn.XLOOKUP(B14,'Format-Blr'!$B$51:$B$88,'Format-Blr'!J$51:J$88) -> 0 | AD14: =_xlfn.XLOOKUP(B14,'Format-Blr'!$B$51:$B$88,'Format-Blr'!P$51:P$88) -> 0 | AE14: =_xlfn.XLOOKUP(B14,'Format-Blr'!$B$51:$B$88,'Format-Blr'!Q$51:Q$88) -> 0 | AF14: =_xlfn.XLOOKUP(B14,'Format-Blr'!$B$51:$B$88,'Format-Blr'!W$51:W$88) -> 0 | AG14: =_xlfn.XLOOKUP(B14,'Format-Blr'!$B$51:$B$88,'Format-Blr'!X$51:X$88) -> 0 | AH14: =_xlfn.XLOOKUP(B14,'Format-Blr'!$B$51:$B$88,'Format-Blr'!AD$51:AD$88) -> 0 | AI14: =_xlfn.XLOOKUP(B14,'Format-Blr'!$B$51:$B$88,'Format-Blr'!AE$51:AE$88) -> 0 | AJ14: =_xlfn.XLOOKUP(B14,'Format-Blr'!$B$51:$B$88,'Format-Blr'!AK$51:AK$88) -> 0 | AK14: =_xlfn.XLOOKUP(B14,'Format-Blr'!$B$51:$B$88,'Format-Blr'!AL$51:AL$88) -> 0 | AL14: =_xlfn.XLOOKUP(B14,'Format-Blr'!$B$51:$B$88,'Format-Blr'!AR$51:AR$88) -> 71 | AM14: =_xlfn.XLOOKUP(B14,'Format-Blr'!$B$51:$B$88,'Format-Blr'!AS$51:AS$88) -> 10 | AN14: =_xlfn.XLOOKUP(B14,'Format-Blr'!$B$51:$B$88,'Format-Blr'!AY$51:AY$88) -> 0 | AO14: =_xlfn.XLOOKUP(B14,'Format-Blr'!$B$51:$B$88,'Format-Blr'!AZ$51:AZ$88) -> 0 | AP14: =_xlfn.XLOOKUP(B14,'Format-Blr'!$B$51:$B$88,'Format-Blr'!BF$51:BF$88) -> 0 | AQ14: =_xlfn.XLOOKUP(B14,'Format-Blr'!$B$51:$B$88,'Format-Blr'!BG$51:BG$88) -> 0 | AR14: =_xlfn.XLOOKUP(B14,'Format-Blr'!$B$51:$B$88,'Format-Blr'!BM$51:BM$88) -> 0 | AS14: =_xlfn.XLOOKUP(B14,'Format-Blr'!$B$51:$B$88,'Format-Blr'!BN$51:BN$88) -> 0 | AT14: =_xlfn.XLOOKUP(B14,'Format-Blr'!$B$51:$B$88,'Format-Blr'!BT$51:BT$88) -> 0 | AU14: =_xlfn.XLOOKUP(B14,'Format-Blr'!$B$51:$B$88,'Format-Blr'!BU$51:BU$88) -> 0 | AV14: =SUM(AB14,AD14,AF14,AH14,AJ14,AL14,AN14,AP14,AR14,AT14) -> 71 | AW14: =SUM(AC14,AE14,AG14,AI14,AK14,AM14,AO14,AQ14,AS14,AU14) -> 10 | AX14: =AW14/AV14*100 -> 14.084507 | AY14: =_xlfn.XLOOKUP(B14,'Format-Blr'!B$51:B$88,'Format-Blr'!CF$51:CF$88) -> 0 | AZ14: =_xlfn.XLOOKUP(B14,'Format-Blr'!B$51:B$88,'Format-Blr'!CG$51:CG$88) -> 0 | BA14: =AZ14/AY14*100 -> #DIV/0! | BB14: =_xlfn.XLOOKUP(B14,'Format-Blr'!$B$7:$B$44,'Format-Blr'!CF$7:CF$44) -> 0 | BC14: =_xlfn.XLOOKUP(B14,'Format-Blr'!$B$7:$B$44,'Format-Blr'!CG$7:CG$44) -> 0 | BD14: =_xlfn.XLOOKUP(B14,'Format-Blr'!$B$7:$B$44,'Format-Blr'!CI$7:CI$44) -> 0 | BE14: =_xlfn.XLOOKUP(B14,'Format-Blr'!$B$7:$B$44,'Format-Blr'!CJ$7:CJ$44) -> 0 | BF14: =_xlfn.XLOOKUP(B14,'Format-Blr'!$B$7:$B$44,'Format-Blr'!CL$7:CL$44) -> 0 | BG14: =_xlfn.XLOOKUP(B14,'Format-Blr'!$B$7:$B$44,'Format-Blr'!CM$7:CM$44) -> 0 | BH14: =_xlfn.XLOOKUP(B14,'Format-Blr'!$B$7:$B$44,'Format-Blr'!CO$7:CO$44) -> 0 | BI14: =_xlfn.XLOOKUP(B14,'Format-Blr'!$B$7:$B$44,'Format-Blr'!CP$7:CP$44) -> 0 | BJ14: =SUM(BB14,BD14,BF14,BH14) -> 0 | BK14: =SUM(BC14,BE14,BG14,BI14) -> 0 | BL14: =BK14/BJ14*100 -> #DIV/0! | BN14: =SUM(Y14,AV14,AY14,BJ14) -> 192 | BO14: =SUM(Z14,AW14,AZ14,BK14) -> 107 | BP14: =BO14/BN14*100 -> 55.729167
A15: BANGALORE | B15: RAJAJI NAGAR | C15: DAY | D15: COED | E15: =_xlfn.XLOOKUP(B15,'Format-Blr'!$B$7:$B$44,'Format-Blr'!I$7:I$44) -> 0 | F15: =_xlfn.XLOOKUP(B15,'Format-Blr'!$B$7:$B$44,'Format-Blr'!J$7:J$44) -> 0 | G15: =_xlfn.XLOOKUP(B15,'Format-Blr'!$B$7:$B$44,'Format-Blr'!P$7:P$44) -> 0 | H15: =_xlfn.XLOOKUP(B15,'Format-Blr'!$B$7:$B$44,'Format-Blr'!Q$7:Q$44) -> 0 | I15: =_xlfn.XLOOKUP(B15,'Format-Blr'!$B$7:$B$44,'Format-Blr'!W$7:W$44) -> 46 | J15: =_xlfn.XLOOKUP(B15,'Format-Blr'!$B$7:$B$44,'Format-Blr'!X$7:X$44) -> 43 | K15: =_xlfn.XLOOKUP(B15,'Format-Blr'!$B$7:$B$44,'Format-Blr'!AD$7:AD$44) -> 0 | L15: =_xlfn.XLOOKUP(B15,'Format-Blr'!$B$7:$B$44,'Format-Blr'!AE$7:AE$44) -> 0 | M15: =_xlfn.XLOOKUP(B15,'Format-Blr'!$B$7:$B$44,'Format-Blr'!AK$7:AK$44) -> 35 | N15: =_xlfn.XLOOKUP(B15,'Format-Blr'!$B$7:$B$44,'Format-Blr'!AL$7:AL$44) -> 32 | O15: =_xlfn.XLOOKUP(B15,'Format-Blr'!$B$7:$B$44,'Format-Blr'!AR$7:AR$44) -> 261 | P15: =_xlfn.XLOOKUP(B15,'Format-Blr'!$B$7:$B$44,'Format-Blr'!AS$7:AS$44) -> 243 | Q15: =_xlfn.XLOOKUP(B15,'Format-Blr'!$B$7:$B$44,'Format-Blr'!AY$7:AY$44) -> 53 | R15: =_xlfn.XLOOKUP(B15,'Format-Blr'!$B$7:$B$44,'Format-Blr'!AZ$7:AZ$44) -> 51 | S15: =_xlfn.XLOOKUP(B15,'Format-Blr'!$B$7:$B$44,'Format-Blr'!BF$7:BF$44) -> 58 | T15: =_xlfn.XLOOKUP(B15,'Format-Blr'!$B$7:$B$44,'Format-Blr'!BG$7:BG$44) -> 56 | U15: =_xlfn.XLOOKUP(B15,'Format-Blr'!$B$7:$B$44,'Format-Blr'!BM$7:BM$44) -> 0 | V15: =_xlfn.XLOOKUP(B15,'Format-Blr'!$B$7:$B$44,'Format-Blr'!BN$7:BN$44) -> 0 | W15: =_xlfn.XLOOKUP(B15,'Format-Blr'!$B$7:$B$44,'Format-Blr'!BT$7:BT$44) -> 61 | X15: =_xlfn.XLOOKUP(B15,'Format-Blr'!$B$7:$B$44,'Format-Blr'!BU$7:BU$44) -> 56 | Y15: =SUM(E15,G15,I15,K15,M15,O15,Q15,S15,U15,W15) -> 514 | Z15: =SUM(F15,H15,J15,L15,N15,P15,R15,T15,V15,X15) -> 481 | AA15: =Z15/Y15*100 -> 93.579767 | AB15: =_xlfn.XLOOKUP(B15,'Format-Blr'!$B$51:$B$88,'Format-Blr'!I$51:I$88) -> 0 | AC15: =_xlfn.XLOOKUP(B15,'Format-Blr'!$B$51:$B$88,'Format-Blr'!J$51:J$88) -> 0 | AD15: =_xlfn.XLOOKUP(B15,'Format-Blr'!$B$51:$B$88,'Format-Blr'!P$51:P$88) -> 0 | AE15: =_xlfn.XLOOKUP(B15,'Format-Blr'!$B$51:$B$88,'Format-Blr'!Q$51:Q$88) -> 0 | AF15: =_xlfn.XLOOKUP(B15,'Format-Blr'!$B$51:$B$88,'Format-Blr'!W$51:W$88) -> 40 | AG15: =_xlfn.XLOOKUP(B15,'Format-Blr'!$B$51:$B$88,'Format-Blr'!X$51:X$88) -> 19 | AH15: =_xlfn.XLOOKUP(B15,'Format-Blr'!$B$51:$B$88,'Format-Blr'!AD$51:AD$88) -> 0 | AI15: =_xlfn.XLOOKUP(B15,'Format-Blr'!$B$51:$B$88,'Format-Blr'!AE$51:AE$88) -> 0 | AJ15: =_xlfn.XLOOKUP(B15,'Format-Blr'!$B$51:$B$88,'Format-Blr'!AK$51:AK$88) -> 40 | AK15: =_xlfn.XLOOKUP(B15,'Format-Blr'!$B$51:$B$88,'Format-Blr'!AL$51:AL$88) -> 28 | AL15: =_xlfn.XLOOKUP(B15,'Format-Blr'!$B$51:$B$88,'Format-Blr'!AR$51:AR$88) -> 229 | AM15: =_xlfn.XLOOKUP(B15,'Format-Blr'!$B$51:$B$88,'Format-Blr'!AS$51:AS$88) -> 119 | AN15: =_xlfn.XLOOKUP(B15,'Format-Blr'!$B$51:$B$88,'Format-Blr'!AY$51:AY$88) -> 60 | AO15: =_xlfn.XLOOKUP(B15,'Format-Blr'!$B$51:$B$88,'Format-Blr'!AZ$51:AZ$88) -> 37 | AP15: =_xlfn.XLOOKUP(B15,'Format-Blr'!$B$51:$B$88,'Format-Blr'!BF$51:BF$88) -> 63 | AQ15: =_xlfn.XLOOKUP(B15,'Format-Blr'!$B$51:$B$88,'Format-Blr'!BG$51:BG$88) -> 34 | AR15: =_xlfn.XLOOKUP(B15,'Format-Blr'!$B$51:$B$88,'Format-Blr'!BM$51:BM$88) -> 0 | AS15: =_xlfn.XLOOKUP(B15,'Format-Blr'!$B$51:$B$88,'Format-Blr'!BN$51:BN$88) -> 0 | AT15: =_xlfn.XLOOKUP(B15,'Format-Blr'!$B$51:$B$88,'Format-Blr'!BT$51:BT$88) -> 54 | AU15: =_xlfn.XLOOKUP(B15,'Format-Blr'!$B$51:$B$88,'Format-Blr'!BU$51:BU$88) -> 38 | AV15: =SUM(AB15,AD15,AF15,AH15,AJ15,AL15,AN15,AP15,AR15,AT15) -> 486 | AW15: =SUM(AC15,AE15,AG15,AI15,AK15,AM15,AO15,AQ15,AS15,AU15) -> 275 | AX15: =AW15/AV15*100 -> 56.584362 | AY15: =_xlfn.XLOOKUP(B15,'Format-Blr'!B$51:B$88,'Format-Blr'!CF$51:CF$88) -> 0 | AZ15: =_xlfn.XLOOKUP(B15,'Format-Blr'!B$51:B$88,'Format-Blr'!CG$51:CG$88) -> 0 | BA15: =AZ15/AY15*100 -> #DIV/0! | BB15: =_xlfn.XLOOKUP(B15,'Format-Blr'!$B$7:$B$44,'Format-Blr'!CF$7:CF$44) -> 0 | BC15: =_xlfn.XLOOKUP(B15,'Format-Blr'!$B$7:$B$44,'Format-Blr'!CG$7:CG$44) -> 0 | BD15: =_xlfn.XLOOKUP(B15,'Format-Blr'!$B$7:$B$44,'Format-Blr'!CI$7:CI$44) -> 0 | BE15: =_xlfn.XLOOKUP(B15,'Format-Blr'!$B$7:$B$44,'Format-Blr'!CJ$7:CJ$44) -> 0 | BF15: =_xlfn.XLOOKUP(B15,'Format-Blr'!$B$7:$B$44,'Format-Blr'!CL$7:CL$44) -> 0 | BG15: =_xlfn.XLOOKUP(B15,'Format-Blr'!$B$7:$B$44,'Format-Blr'!CM$7:CM$44) -> 0 | BH15: =_xlfn.XLOOKUP(B15,'Format-Blr'!$B$7:$B$44,'Format-Blr'!CO$7:CO$44) -> 0 | BI15: =_xlfn.XLOOKUP(B15,'Format-Blr'!$B$7:$B$44,'Format-Blr'!CP$7:CP$44) -> 0 | BJ15: =SUM(BB15,BD15,BF15,BH15) -> 0 | BK15: =SUM(BC15,BE15,BG15,BI15) -> 0 | BL15: =BK15/BJ15*100 -> #DIV/0! | BN15: =SUM(Y15,AV15,AY15,BJ15) -> 1000 | BO15: =SUM(Z15,AW15,AZ15,BK15) -> 756 | BP15: =BO15/BN15*100 -> 75.6
A16: BANGALORE | B16: SESHADRIPURAM | C16: DAY | D16: COED | E16: =_xlfn.XLOOKUP(B16,'Format-Blr'!$B$7:$B$44,'Format-Blr'!I$7:I$44) -> 0 | F16: =_xlfn.XLOOKUP(B16,'Format-Blr'!$B$7:$B$44,'Format-Blr'!J$7:J$44) -> 0 | G16: =_xlfn.XLOOKUP(B16,'Format-Blr'!$B$7:$B$44,'Format-Blr'!P$7:P$44) -> 0 | H16: =_xlfn.XLOOKUP(B16,'Format-Blr'!$B$7:$B$44,'Format-Blr'!Q$7:Q$44) -> 0 | I16: =_xlfn.XLOOKUP(B16,'Format-Blr'!$B$7:$B$44,'Format-Blr'!W$7:W$44) -> 61 | J16: =_xlfn.XLOOKUP(B16,'Format-Blr'!$B$7:$B$44,'Format-Blr'!X$7:X$44) -> 49 | K16: =_xlfn.XLOOKUP(B16,'Format-Blr'!$B$7:$B$44,'Format-Blr'!AD$7:AD$44) -> 0 | L16: =_xlfn.XLOOKUP(B16,'Format-Blr'!$B$7:$B$44,'Format-Blr'!AE$7:AE$44) -> 0 | M16: =_xlfn.XLOOKUP(B16,'Format-Blr'!$B$7:$B$44,'Format-Blr'!AK$7:AK$44) -> 53 | N16: =_xlfn.XLOOKUP(B16,'Format-Blr'!$B$7:$B$44,'Format-Blr'!AL$7:AL$44) -> 50 | O16: =_xlfn.XLOOKUP(B16,'Format-Blr'!$B$7:$B$44,'Format-Blr'!AR$7:AR$44) -> 58 | P16: =_xlfn.XLOOKUP(B16,'Format-Blr'!$B$7:$B$44,'Format-Blr'!AS$7:AS$44) -> 54 | Q16: =_xlfn.XLOOKUP(B16,'Format-Blr'!$B$7:$B$44,'Format-Blr'!AY$7:AY$44) -> 54 | R16: =_xlfn.XLOOKUP(B16,'Format-Blr'!$B$7:$B$44,'Format-Blr'!AZ$7:AZ$44) -> 50 | S16: =_xlfn.XLOOKUP(B16,'Format-Blr'!$B$7:$B$44,'Format-Blr'!BF$7:BF$44) -> 0 | T16: =_xlfn.XLOOKUP(B16,'Format-Blr'!$B$7:$B$44,'Format-Blr'!BG$7:BG$44) -> 0 | U16: =_xlfn.XLOOKUP(B16,'Format-Blr'!$B$7:$B$44,'Format-Blr'!BM$7:BM$44) -> 0 | V16: =_xlfn.XLOOKUP(B16,'Format-Blr'!$B$7:$B$44,'Format-Blr'!BN$7:BN$44) -> 0 | W16: =_xlfn.XLOOKUP(B16,'Format-Blr'!$B$7:$B$44,'Format-Blr'!BT$7:BT$44) -> 0 | X16: =_xlfn.XLOOKUP(B16,'Format-Blr'!$B$7:$B$44,'Format-Blr'!BU$7:BU$44) -> 0 | Y16: =SUM(E16,G16,I16,K16,M16,O16,Q16,S16,U16,W16) -> 226 | Z16: =SUM(F16,H16,J16,L16,N16,P16,R16,T16,V16,X16) -> 203 | AA16: =Z16/Y16*100 -> 89.823009 | AB16: =_xlfn.XLOOKUP(B16,'Format-Blr'!$B$51:$B$88,'Format-Blr'!I$51:I$88) -> 0 | AC16: =_xlfn.XLOOKUP(B16,'Format-Blr'!$B$51:$B$88,'Format-Blr'!J$51:J$88) -> 0 | AD16: =_xlfn.XLOOKUP(B16,'Format-Blr'!$B$51:$B$88,'Format-Blr'!P$51:P$88) -> 0 | AE16: =_xlfn.XLOOKUP(B16,'Format-Blr'!$B$51:$B$88,'Format-Blr'!Q$51:Q$88) -> 0 | AF16: =_xlfn.XLOOKUP(B16,'Format-Blr'!$B$51:$B$88,'Format-Blr'!W$51:W$88) -> 41 | AG16: =_xlfn.XLOOKUP(B16,'Format-Blr'!$B$51:$B$88,'Format-Blr'!X$51:X$88) -> 5 | AH16: =_xlfn.XLOOKUP(B16,'Format-Blr'!$B$51:$B$88,'Format-Blr'!AD$51:AD$88) -> 0 | AI16: =_xlfn.XLOOKUP(B16,'Format-Blr'!$B$51:$B$88,'Format-Blr'!AE$51:AE$88) -> 0 | AJ16: =_xlfn.XLOOKUP(B16,'Format-Blr'!$B$51:$B$88,'Format-Blr'!AK$51:AK$88) -> 57 | AK16: =_xlfn.XLOOKUP(B16,'Format-Blr'!$B$51:$B$88,'Format-Blr'!AL$51:AL$88) -> 16 | AL16: =_xlfn.XLOOKUP(B16,'Format-Blr'!$B$51:$B$88,'Format-Blr'!AR$51:AR$88) -> 62 | AM16: =_xlfn.XLOOKUP(B16,'Format-Blr'!$B$51:$B$88,'Format-Blr'!AS$51:AS$88) -> 19 | AN16: =_xlfn.XLOOKUP(B16,'Format-Blr'!$B$51:$B$88,'Format-Blr'!AY$51:AY$88) -> 26 | AO16: =_xlfn.XLOOKUP(B16,'Format-Blr'!$B$51:$B$88,'Format-Blr'!AZ$51:AZ$88) -> 14 | AP16: =_xlfn.XLOOKUP(B16,'Format-Blr'!$B$51:$B$88,'Format-Blr'!BF$51:BF$88) -> 0 | AQ16: =_xlfn.XLOOKUP(B16,'Format-Blr'!$B$51:$B$88,'Format-Blr'!BG$51:BG$88) -> 0 | AR16: =_xlfn.XLOOKUP(B16,'Format-Blr'!$B$51:$B$88,'Format-Blr'!BM$51:BM$88) -> 0 | AS16: =_xlfn.XLOOKUP(B16,'Format-Blr'!$B$51:$B$88,'Format-Blr'!BN$51:BN$88) -> 0 | AT16: =_xlfn.XLOOKUP(B16,'Format-Blr'!$B$51:$B$88,'Format-Blr'!BT$51:BT$88) -> 49 | AU16: =_xlfn.XLOOKUP(B16,'Format-Blr'!$B$51:$B$88,'Format-Blr'!BU$51:BU$88) -> 14 | AV16: =SUM(AB16,AD16,AF16,AH16,AJ16,AL16,AN16,AP16,AR16,AT16) -> 235 | AW16: =SUM(AC16,AE16,AG16,AI16,AK16,AM16,AO16,AQ16,AS16,AU16) -> 68 | AX16: =AW16/AV16*100 -> 28.93617 | AY16: =_xlfn.XLOOKUP(B16,'Format-Blr'!B$51:B$88,'Format-Blr'!CF$51:CF$88) -> 0 | AZ16: =_xlfn.XLOOKUP(B16,'Format-Blr'!B$51:B$88,'Format-Blr'!CG$51:CG$88) -> 0 | BA16: =AZ16/AY16*100 -> #DIV/0! | BB16: =_xlfn.XLOOKUP(B16,'Format-Blr'!$B$7:$B$44,'Format-Blr'!CF$7:CF$44) -> 0 | BC16: =_xlfn.XLOOKUP(B16,'Format-Blr'!$B$7:$B$44,'Format-Blr'!CG$7:CG$44) -> 0 | BD16: =_xlfn.XLOOKUP(B16,'Format-Blr'!$B$7:$B$44,'Format-Blr'!CI$7:CI$44) -> 0 | BE16: =_xlfn.XLOOKUP(B16,'Format-Blr'!$B$7:$B$44,'Format-Blr'!CJ$7:CJ$44) -> 0 | BF16: =_xlfn.XLOOKUP(B16,'Format-Blr'!$B$7:$B$44,'Format-Blr'!CL$7:CL$44) -> 0 | BG16: =_xlfn.XLOOKUP(B16,'Format-Blr'!$B$7:$B$44,'Format-Blr'!CM$7:CM$44) -> 0 | BH16: =_xlfn.XLOOKUP(B16,'Format-Blr'!$B$7:$B$44,'Format-Blr'!CO$7:CO$44) -> 0 | BI16: =_xlfn.XLOOKUP(B16,'Format-Blr'!$B$7:$B$44,'Format-Blr'!CP$7:CP$44) -> 0 | BJ16: =SUM(BB16,BD16,BF16,BH16) -> 0 | BK16: =SUM(BC16,BE16,BG16,BI16) -> 0 | BL16: =BK16/BJ16*100 -> #DIV/0! | BN16: =SUM(Y16,AV16,AY16,BJ16) -> 461 | BO16: =SUM(Z16,AW16,AZ16,BK16) -> 271 | BP16: =BO16/BN16*100 -> 58.785249
A17: BANGALORE | B17: VIDYARANYAPURA | C17: DAY | D17: COED | E17: =_xlfn.XLOOKUP(B17,'Format-Blr'!$B$7:$B$44,'Format-Blr'!I$7:I$44) -> 46 | F17: =_xlfn.XLOOKUP(B17,'Format-Blr'!$B$7:$B$44,'Format-Blr'!J$7:J$44) -> 35 | G17: =_xlfn.XLOOKUP(B17,'Format-Blr'!$B$7:$B$44,'Format-Blr'!P$7:P$44) -> 0 | H17: =_xlfn.XLOOKUP(B17,'Format-Blr'!$B$7:$B$44,'Format-Blr'!Q$7:Q$44) -> 0 | I17: =_xlfn.XLOOKUP(B17,'Format-Blr'!$B$7:$B$44,'Format-Blr'!W$7:W$44) -> 67 | J17: =_xlfn.XLOOKUP(B17,'Format-Blr'!$B$7:$B$44,'Format-Blr'!X$7:X$44) -> 55 | K17: =_xlfn.XLOOKUP(B17,'Format-Blr'!$B$7:$B$44,'Format-Blr'!AD$7:AD$44) -> 0 | L17: =_xlfn.XLOOKUP(B17,'Format-Blr'!$B$7:$B$44,'Format-Blr'!AE$7:AE$44) -> 0 | M17: =_xlfn.XLOOKUP(B17,'Format-Blr'!$B$7:$B$44,'Format-Blr'!AK$7:AK$44) -> 60 | N17: =_xlfn.XLOOKUP(B17,'Format-Blr'!$B$7:$B$44,'Format-Blr'!AL$7:AL$44) -> 48 | O17: =_xlfn.XLOOKUP(B17,'Format-Blr'!$B$7:$B$44,'Format-Blr'!AR$7:AR$44) -> 101 | P17: =_xlfn.XLOOKUP(B17,'Format-Blr'!$B$7:$B$44,'Format-Blr'!AS$7:AS$44) -> 78 | Q17: =_xlfn.XLOOKUP(B17,'Format-Blr'!$B$7:$B$44,'Format-Blr'!AY$7:AY$44) -> 55 | R17: =_xlfn.XLOOKUP(B17,'Format-Blr'!$B$7:$B$44,'Format-Blr'!AZ$7:AZ$44) -> 40 | S17: =_xlfn.XLOOKUP(B17,'Format-Blr'!$B$7:$B$44,'Format-Blr'!BF$7:BF$44) -> 0 | T17: =_xlfn.XLOOKUP(B17,'Format-Blr'!$B$7:$B$44,'Format-Blr'!BG$7:BG$44) -> 0 | U17: =_xlfn.XLOOKUP(B17,'Format-Blr'!$B$7:$B$44,'Format-Blr'!BM$7:BM$44) -> 0 | V17: =_xlfn.XLOOKUP(B17,'Format-Blr'!$B$7:$B$44,'Format-Blr'!BN$7:BN$44) -> 0 | W17: =_xlfn.XLOOKUP(B17,'Format-Blr'!$B$7:$B$44,'Format-Blr'!BT$7:BT$44) -> 51 | X17: =_xlfn.XLOOKUP(B17,'Format-Blr'!$B$7:$B$44,'Format-Blr'!BU$7:BU$44) -> 43 | Y17: =SUM(E17,G17,I17,K17,M17,O17,Q17,S17,U17,W17) -> 380 | Z17: =SUM(F17,H17,J17,L17,N17,P17,R17,T17,V17,X17) -> 299 | AA17: =Z17/Y17*100 -> 78.684211 | AB17: =_xlfn.XLOOKUP(B17,'Format-Blr'!$B$51:$B$88,'Format-Blr'!I$51:I$88) -> 48 | AC17: =_xlfn.XLOOKUP(B17,'Format-Blr'!$B$51:$B$88,'Format-Blr'!J$51:J$88) -> 7 | AD17: =_xlfn.XLOOKUP(B17,'Format-Blr'!$B$51:$B$88,'Format-Blr'!P$51:P$88) -> 25 | AE17: =_xlfn.XLOOKUP(B17,'Format-Blr'!$B$51:$B$88,'Format-Blr'!Q$51:Q$88) -> 2 | AF17: =_xlfn.XLOOKUP(B17,'Format-Blr'!$B$51:$B$88,'Format-Blr'!W$51:W$88) -> 52 | AG17: =_xlfn.XLOOKUP(B17,'Format-Blr'!$B$51:$B$88,'Format-Blr'!X$51:X$88) -> 8 | AH17: =_xlfn.XLOOKUP(B17,'Format-Blr'!$B$51:$B$88,'Format-Blr'!AD$51:AD$88) -> 0 | AI17: =_xlfn.XLOOKUP(B17,'Format-Blr'!$B$51:$B$88,'Format-Blr'!AE$51:AE$88) -> 0 | AJ17: =_xlfn.XLOOKUP(B17,'Format-Blr'!$B$51:$B$88,'Format-Blr'!AK$51:AK$88) -> 67 | AK17: =_xlfn.XLOOKUP(B17,'Format-Blr'!$B$51:$B$88,'Format-Blr'!AL$51:AL$88) -> 11 | AL17: =_xlfn.XLOOKUP(B17,'Format-Blr'!$B$51:$B$88,'Format-Blr'!AR$51:AR$88) -> 62 | AM17: =_xlfn.XLOOKUP(B17,'Format-Blr'!$B$51:$B$88,'Format-Blr'!AS$51:AS$88) -> 20 | AN17: =_xlfn.XLOOKUP(B17,'Format-Blr'!$B$51:$B$88,'Format-Blr'!AY$51:AY$88) -> 45 | AO17: =_xlfn.XLOOKUP(B17,'Format-Blr'!$B$51:$B$88,'Format-Blr'!AZ$51:AZ$88) -> 13 | AP17: =_xlfn.XLOOKUP(B17,'Format-Blr'!$B$51:$B$88,'Format-Blr'!BF$51:BF$88) -> 0 | AQ17: =_xlfn.XLOOKUP(B17,'Format-Blr'!$B$51:$B$88,'Format-Blr'!BG$51:BG$88) -> 0 | AR17: =_xlfn.XLOOKUP(B17,'Format-Blr'!$B$51:$B$88,'Format-Blr'!BM$51:BM$88) -> 0 | AS17: =_xlfn.XLOOKUP(B17,'Format-Blr'!$B$51:$B$88,'Format-Blr'!BN$51:BN$88) -> 0 | AT17: =_xlfn.XLOOKUP(B17,'Format-Blr'!$B$51:$B$88,'Format-Blr'!BT$51:BT$88) -> 66 | AU17: =_xlfn.XLOOKUP(B17,'Format-Blr'!$B$51:$B$88,'Format-Blr'!BU$51:BU$88) -> 8 | AV17: =SUM(AB17,AD17,AF17,AH17,AJ17,AL17,AN17,AP17,AR17,AT17) -> 365 | AW17: =SUM(AC17,AE17,AG17,AI17,AK17,AM17,AO17,AQ17,AS17,AU17) -> 69 | AX17: =AW17/AV17*100 -> 18.90411 | AY17: =_xlfn.XLOOKUP(B17,'Format-Blr'!B$51:B$88,'Format-Blr'!CF$51:CF$88) -> 0 | AZ17: =_xlfn.XLOOKUP(B17,'Format-Blr'!B$51:B$88,'Format-Blr'!CG$51:CG$88) -> 0 | BA17: =AZ17/AY17*100 -> #DIV/0! | BB17: =_xlfn.XLOOKUP(B17,'Format-Blr'!$B$7:$B$44,'Format-Blr'!CF$7:CF$44) -> 32 | BC17: =_xlfn.XLOOKUP(B17,'Format-Blr'!$B$7:$B$44,'Format-Blr'!CG$7:CG$44) -> 17 | BD17: =_xlfn.XLOOKUP(B17,'Format-Blr'!$B$7:$B$44,'Format-Blr'!CI$7:CI$44) -> 40 | BE17: =_xlfn.XLOOKUP(B17,'Format-Blr'!$B$7:$B$44,'Format-Blr'!CJ$7:CJ$44) -> 19 | BF17: =_xlfn.XLOOKUP(B17,'Format-Blr'!$B$7:$B$44,'Format-Blr'!CL$7:CL$44) -> 50 | BG17: =_xlfn.XLOOKUP(B17,'Format-Blr'!$B$7:$B$44,'Format-Blr'!CM$7:CM$44) -> 43 | BH17: =_xlfn.XLOOKUP(B17,'Format-Blr'!$B$7:$B$44,'Format-Blr'!CO$7:CO$44) -> 30 | BI17: =_xlfn.XLOOKUP(B17,'Format-Blr'!$B$7:$B$44,'Format-Blr'!CP$7:CP$44) -> 30 | BJ17: =SUM(BB17,BD17,BF17,BH17) -> 152 | BK17: =SUM(BC17,BE17,BG17,BI17) -> 109 | BL17: =BK17/BJ17*100 -> 71.710526 | BN17: =SUM(Y17,AV17,AY17,BJ17) -> 897 | BO17: =SUM(Z17,AW17,AZ17,BK17) -> 477 | BP17: =BO17/BN17*100 -> 53.177258
